Workbook

Sheet Summary
A1: PA DIGITAL COMPETITIVE REPORT
A3: RACE | B3: PLATFORM | C3: TOTAL SPEND | D3: GOP TOTAL | E3: DEM TOTAL | F3: DELTA (DEM-GOP)
A4: State House District 13 | B4: CTV | C4: =SUMIFS('HD-13'!D$4:D$10,'HD-13'!$C$4:$C$10,"CTV") -> 0 | D4: =SUMIFS('HD-13'!D$4:D$10,'HD-13'!$C$4:$C$10,"CTV",'HD-13'!$B$4:$B$10,"R") -> 0 | E4: =SUMIFS('HD-13'!D$4:D$10,'HD-13'!$C$4:$C$10,"CTV",'HD-13'!$B$4:$B$10,"D") -> 0 | F4: =E4-D4 -> 0
B5: Google | C5: =SUMIFS('HD-13'!D$4:D$10,'HD-13'!$C$4:$C$10,"Google") -> 7415.48 | D5: =SUMIFS('HD-13'!D$4:D$10,'HD-13'!$C$4:$C$10,"Google",'HD-13'!$B$4:$B$10,"R") -> 7415.48 | E5: =SUMIFS('HD-13'!D$4:D$10,'HD-13'!$C$4:$C$10,"Google",'HD-13'!$B$4:$B$10,"D") -> 0 | F5: =E5-D5 -> -7415.48
B6: Facebook | C6: =SUMIFS('HD-13'!D$4:D$10,'HD-13'!$C$4:$C$10,"Facebook") -> 954.09 | D6: =SUMIFS('HD-13'!D$4:D$10,'HD-13'!$C$4:$C$10,"Facebook",'HD-13'!$B$4:$B$10,"R") -> 954.09 | E6: =SUMIFS('HD-13'!D$4:D$10,'HD-13'!$C$4:$C$10,"Facebook",'HD-13'!$B$4:$B$10,"D") -> 0 | F6: =E6-D6 -> -954.09
B7: SUBTOTAL | C7: ='HD-13'!D10 -> 8369.57 | D7: ='HD-13'!D8 -> 8369.57 | E7: =0 -> 0 | F7: =E7-D7 -> -8369.57
A9: State House District 16 | B9: CTV | C9: =SUMIFS('HD-16'!D$4:D$12,'HD-16'!$C$4:$C$12,"CTV") -> 510.91 | D9: =SUMIFS('HD-16'!D$4:D$12,'HD-16'!$C$4:$C$12,"CTV",'HD-16'!$B$4:$B$12,"R") -> 0 | E9: =SUMIFS('HD-16'!D$4:D$12,'HD-16'!$C$4:$C$12,"CTV",'HD-16'!$B$4:$B$12,"D") -> 510.91 | F9: =E9-D9 -> 510.91
B10: Google | C10: =SUMIFS('HD-16'!D$4:D$12,'HD-16'!$C$4:$C$12,"Google") -> 0 | D10: =SUMIFS('HD-16'!D$4:D$12,'HD-16'!$C$4:$C$12,"Google",'HD-16'!$B$4:$B$12,"R") -> 0 | E10: =SUMIFS('HD-16'!D$4:D$12,'HD-16'!$C$4:$C$12,"Google",'HD-16'!$B$4:$B$12,"D") -> 0 | F10: =E10-D10 -> 0
B11: Facebook | C11: =SUMIFS('HD-16'!D$4:D$12,'HD-16'!$C$4:$C$12,"Facebook") -> 1685.02 | D11: =SUMIFS('HD-16'!D$4:D$12,'HD-16'!$C$4:$C$12,"Facebook",'HD-16'!$B$4:$B$12,"R") -> 0 | E11: =SUMIFS('HD-16'!D$4:D$12,'HD-16'!$C$4:$C$12,"Facebook",'HD-16'!$B$4:$B$12,"D") -> 1685.02 | F11: =E11-D11 -> 1685.02
B12: SUBTOTAL | C12: ='HD-16'!D12 -> 2195.93 | D12: =0 -> 0 | E12: ='HD-16'!D10 -> 2195.93 | F12: =E12-D12 -> 2195.93
A14: State House District 18 | B14: CTV | C14: =SUMIFS('HD-18'!D$4:D$17,'HD-18'!$C$4:$C$17,"CTV") -> 291.25 | D14: =SUMIFS('HD-18'!D$4:D$17,'HD-18'!$C$4:$C$17,"CTV",'HD-18'!$B$4:$B$17,"R") -> 0 | E14: =SUMIFS('HD-18'!D$4:D$17,'HD-18'!$C$4:$C$17,"CTV",'HD-18'!$B$4:$B$17,"D") -> 291.25 | F14: =E14-D14 -> 291.25
B15: Google | C15: =SUMIFS('HD-18'!D$4:D$17,'HD-18'!$C$4:$C$17,"Google") -> 8812.82 | D15: =SUMIFS('HD-18'!D$4:D$17,'HD-18'!$C$4:$C$17,"Google",'HD-18'!$B$4:$B$17,"R") -> 7791.26 | E15: =SUMIFS('HD-18'!D$4:D$17,'HD-18'!$C$4:$C$17,"Google",'HD-18'!$B$4:$B$17,"D") -> 1021.56 | F15: =E15-D15 -> -6769.7
B16: Facebook | C16: =SUMIFS('HD-18'!D$4:D$17,'HD-18'!$C$4:$C$17,"Facebook") -> 2895.61 | D16: =SUMIFS('HD-18'!D$4:D$17,'HD-18'!$C$4:$C$17,"Facebook",'HD-18'!$B$4:$B$17,"R") -> 955.43 | E16: =SUMIFS('HD-18'!D$4:D$17,'HD-18'!$C$4:$C$17,"Facebook",'HD-18'!$B$4:$B$17,"D") -> 1940.18 | F16: =E16-D16 -> 984.75
B17: SUBTOTAL | C17: ='HD-18'!D17 -> 11999.68 | D17: ='HD-18'!D8 -> 8746.69 | E17: ='HD-18'!D15 -> 3252.99 | F17: =E17-D17 -> -5493.7
A19: State House District 28 | B19: CTV | C19: =SUMIFS('HD-28'!D$4:D$10,'HD-28'!$C$4:$C$10,"CTV") -> 0 | D19: =SUMIFS('HD-28'!D$4:D$10,'HD-28'!$C$4:$C$10,"CTV",'HD-28'!$B$4:$B$10,"R") -> 0 | E19: =SUMIFS('HD-28'!D$4:D$10,'HD-28'!$C$4:$C$10,"CTV",'HD-28'!$B$4:$B$10,"D") -> 0 | F19: =E19-D19 -> 0
B20: Google | C20: =SUMIFS('HD-28'!D$4:D$10,'HD-28'!$C$4:$C$10,"Google") -> 9958.28 | D20: =SUMIFS('HD-28'!D$4:D$10,'HD-28'!$C$4:$C$10,"Google",'HD-28'!$B$4:$B$10,"R") -> 9958.28 | E20: =SUMIFS('HD-28'!D$4:D$10,'HD-28'!$C$4:$C$10,"Google",'HD-28'!$B$4:$B$10,"D") -> 0 | F20: =E20-D20 -> -9958.28
B21: Facebook | C21: =SUMIFS('HD-28'!D$4:D$10,'HD-28'!$C$4:$C$10,"Facebook") -> 1908.57 | D21: =SUMIFS('HD-28'!D$4:D$10,'HD-28'!$C$4:$C$10,"Facebook",'HD-28'!$B$4:$B$10,"R") -> 1908.57 | E21: =SUMIFS('HD-28'!D$4:D$10,'HD-28'!$C$4:$C$10,"Facebook",'HD-28'!$B$4:$B$10,"D") -> 0 | F21: =E21-D21 -> -1908.57
B22: SUBTOTAL | C22: ='HD-28'!D10 -> 11866.85 | D22: ='HD-28'!D8 -> 11866.85 | E22: =0 -> 0 | F22: =E22-D22 -> -11866.85
A24: State House District 41 | B24: CTV | C24: =SUMIFS('HD-41'!D$4:D$10,'HD-41'!$C$4:$C$10,"CTV") -> 0 | D24: =SUMIFS('HD-41'!D$4:D$10,'HD-41'!$C$4:$C$10,"CTV",'HD-41'!$B$4:$B$10,"R") -> 0 | E24: =SUMIFS('HD-41'!D$4:D$10,'HD-41'!$C$4:$C$10,"CTV",'HD-41'!$B$4:$B$10,"D") -> 0 | F24: =E24-D24 -> 0
B25: Google | C25: =SUMIFS('HD-41'!D$4:D$10,'HD-41'!$C$4:$C$10,"Google") -> 7899.44 | D25: =SUMIFS('HD-41'!D$4:D$10,'HD-41'!$C$4:$C$10,"Google",'HD-41'!$B$4:$B$10,"R") -> 7899.44 | E25: =SUMIFS('HD-41'!D$4:D$10,'HD-41'!$C$4:$C$10,"Google",'HD-41'!$B$4:$B$10,"D") -> 0 | F25: =E25-D25 -> -7899.44
B26: Facebook | C26: =SUMIFS('HD-41'!D$4:D$10,'HD-41'!$C$4:$C$10,"Facebook") -> 901.12 | D26: =SUMIFS('HD-41'!D$4:D$10,'HD-41'!$C$4:$C$10,"Facebook",'HD-41'!$B$4:$B$10,"R") -> 901.12 | E26: =SUMIFS('HD-41'!D$4:D$10,'HD-41'!$C$4:$C$10,"Facebook",'HD-41'!$B$4:$B$10,"D") -> 0 | F26: =E26-D26 -> -901.12
B27: SUBTOTAL | C27: ='HD-41'!D10 -> 8800.56 | D27: ='HD-41'!D8 -> 8800.56 | E27: =0 -> 0 | F27: =E27-D27 -> -8800.56
A29: State House District 44 | B29: CTV | C29: =SUMIFS('HD-44'!D$4:D$23,'HD-44'!$C$4:$C$23,"CTV") -> 985.79 | D29: =SUMIFS('HD-44'!D$4:D$23,'HD-44'!$C$4:$C$23,"CTV",'HD-44'!$B$4:$B$23,"R") -> 0 | E29: =SUMIFS('HD-44'!D$4:D$23,'HD-44'!$C$4:$C$23,"CTV",'HD-44'!$B$4:$B$23,"D") -> 985.79 | F29: =E29-D29 -> 985.79
B30: Google | C30: =SUMIFS('HD-44'!D$4:D$23,'HD-44'!$C$4:$C$23,"Google") -> 13026.89 | D30: =SUMIFS('HD-44'!D$4:D$23,'HD-44'!$C$4:$C$23,"Google",'HD-44'!$B$4:$B$23,"R") -> 9522.05 | E30: =SUMIFS('HD-44'!D$4:D$23,'HD-44'!$C$4:$C$23,"Google",'HD-44'!$B$4:$B$23,"D") -> 3504.84 | F30: =E30-D30 -> -6017.21
B31: Facebook | C31: =SUMIFS('HD-44'!D$4:D$23,'HD-44'!$C$4:$C$23,"Facebook") -> 6641.09 | D31: =SUMIFS('HD-44'!D$4:D$23,'HD-44'!$C$4:$C$23,"Facebook",'HD-44'!$B$4:$B$23,"R") -> 1592.3 | E31: =SUMIFS('HD-44'!D$4:D$23,'HD-44'!$C$4:$C$23,"Facebook",'HD-44'!$B$4:$B$23,"D") -> 5048.79 | F31: =E31-D31 -> 3456.49
B32: SUBTOTAL | C32: ='HD-44'!D23 -> 20653.77 | D32: ='HD-44'!D8 -> 11114.35 | E32: ='HD-44'!D21 -> 9539.42 | F32: =E32-D32 -> -1574.93
A34: State House District 46 | B34: CTV | C34: =SUMIFS('HD-46'!D$4:D$10,'HD-46'!$C$4:$C$10,"CTV") -> 0 | D34: =SUMIFS('HD-46'!D$4:D$10,'HD-46'!$C$4:$C$10,"CTV",'HD-46'!$B$4:$B$10,"R") -> 0 | E34: =SUMIFS('HD-46'!D$4:D$10,'HD-46'!$C$4:$C$10,"CTV",'HD-46'!$B$4:$B$10,"D") -> 0 | F34: =E34-D34 -> 0
B35: Google | C35: =SUMIFS('HD-46'!D$4:D$10,'HD-46'!$C$4:$C$10,"Google") -> 600 | D35: =SUMIFS('HD-46'!D$4:D$10,'HD-46'!$C$4:$C$10,"Google",'HD-46'!$B$4:$B$10,"R") -> 600 | E35: =SUMIFS('HD-46'!D$4:D$10,'HD-46'!$C$4:$C$10,"Google",'HD-46'!$B$4:$B$10,"D") -> 0 | F35: =E35-D35 -> -600
B36: Facebook | C36: =SUMIFS('HD-46'!D$4:D$10,'HD-46'!$C$4:$C$10,"Facebook") -> 1140.3 | D36: =SUMIFS('HD-46'!D$4:D$10,'HD-46'!$C$4:$C$10,"Facebook",'HD-46'!$B$4:$B$10,"R") -> 1140.3 | E36: =SUMIFS('HD-46'!D$4:D$10,'HD-46'!$C$4:$C$10,"Facebook",'HD-46'!$B$4:$B$10,"D") -> 0 | F36: =E36-D36 -> -1140.3
B37: SUBTOTAL | C37: ='HD-46'!D10 -> 1740.3 | D37: ='HD-46'!D8 -> 1740.3 | E37: =0 -> 0 | F37: =E37-D37 -> -1740.3
A39: State House District 72 | B39: CTV | C39: =SUMIFS('HD-72'!D$4:D$26,'HD-72'!$C$4:$C$26,"CTV") -> 67673.63 | D39: =SUMIFS('HD-72'!D$4:D$26,'HD-72'!$C$4:$C$26,"CTV",'HD-72'!$B$4:$B$26,"R") -> 0 | E39: =SUMIFS('HD-72'!D$4:D$26,'HD-72'!$C$4:$C$26,"CTV",'HD-72'!$B$4:$B$26,"D") -> 67673.63 | F39: =E39-D39 -> 67673.63
B40: Google | C40: =SUMIFS('HD-72'!D$4:D$26,'HD-72'!$C$4:$C$26,"Google") -> 22139.3 | D40: =SUMIFS('HD-72'!D$4:D$26,'HD-72'!$C$4:$C$26,"Google",'HD-72'!$B$4:$B$26,"R") -> 19315.89 | E40: =SUMIFS('HD-72'!D$4:D$26,'HD-72'!$C$4:$C$26,"Google",'HD-72'!$B$4:$B$26,"D") -> 2823.41 | F40: =E40-D40 -> -16492.48
B41: Facebook | C41: =SUMIFS('HD-72'!D$4:D$26,'HD-72'!$C$4:$C$26,"Facebook") -> 11303.9 | D41: =SUMIFS('HD-72'!D$4:D$26,'HD-72'!$C$4:$C$26,"Facebook",'HD-72'!$B$4:$B$26,"R") -> 1656.18 | E41: =SUMIFS('HD-72'!D$4:D$26,'HD-72'!$C$4:$C$26,"Facebook",'HD-72'!$B$4:$B$26,"D") -> 9647.72 | F41: =E41-D41 -> 7991.54
B42: SUBTOTAL | C42: ='HD-72'!D26 -> 101116.83 | D42: ='HD-72'!D11 -> 20972.07 | E42: ='HD-72'!D24 -> 80144.76 | F42: =E42-D42 -> 59172.69
A44: State House District 88 | B44: CTV | C44: =SUMIFS('HD-88'!D$4:D$15,'HD-88'!$C$4:$C$15,"CTV") -> 0 | D44: =SUMIFS('HD-88'!D$4:D$15,'HD-88'!$C$4:$C$15,"CTV",'HD-88'!$B$4:$B$15,"R") -> 0 | E44: =SUMIFS('HD-88'!D$4:D$15,'HD-88'!$C$4:$C$15,"CTV",'HD-88'!$B$4:$B$15,"D") -> 0 | F44: =E44-D44 -> 0
B45: Google | C45: =SUMIFS('HD-88'!D$4:D$15,'HD-88'!$C$4:$C$15,"Google") -> 8032.72 | D45: =SUMIFS('HD-88'!D$4:D$15,'HD-88'!$C$4:$C$15,"Google",'HD-88'!$B$4:$B$15,"R") -> 8032.72 | E45: =SUMIFS('HD-88'!D$4:D$15,'HD-88'!$C$4:$C$15,"Google",'HD-88'!$B$4:$B$15,"D") -> 0 | F45: =E45-D45 -> -8032.72
B46: Facebook | C46: =SUMIFS('HD-88'!D$4:D$15,'HD-88'!$C$4:$C$15,"Facebook") -> 3701.28 | D46: =SUMIFS('HD-88'!D$4:D$15,'HD-88'!$C$4:$C$15,"Facebook",'HD-88'!$B$4:$B$15,"R") -> 672.68 | E46: =SUMIFS('HD-88'!D$4:D$15,'HD-88'!$C$4:$C$15,"Facebook",'HD-88'!$B$4:$B$15,"D") -> 3028.6 | F46: =E46-D46 -> 2355.92
B47: SUBTOTAL | C47: ='HD-88'!D15 -> 11734 | D47: ='HD-88'!D8 -> 8705.4 | E47: ='HD-88'!D13 -> 3028.6 | F47: =E47-D47 -> -5676.8
A49: State House District 118 | B49: CTV | C49: =SUMIFS('HD-118'!D$4:D$18,'HD-118'!$C$4:$C$18,"CTV") -> 2510.2 | D49: =SUMIFS('HD-118'!D$4:D$18,'HD-118'!$C$4:$C$18,"CTV",'HD-118'!$B$4:$B$18,"R") -> 0 | E49: =SUMIFS('HD-118'!D$4:D$18,'HD-118'!$C$4:$C$18,"CTV",'HD-118'!$B$4:$B$18,"D") -> 2510.2 | F49: =E49-D49 -> 2510.2
B50: Google | C50: =SUMIFS('HD-118'!D$4:D$18,'HD-118'!$C$4:$C$18,"Google") -> 9883.41 | D50: =SUMIFS('HD-118'!D$4:D$18,'HD-118'!$C$4:$C$18,"Google",'HD-118'!$B$4:$B$18,"R") -> 8287.54 | E50: =SUMIFS('HD-118'!D$4:D$18,'HD-118'!$C$4:$C$18,"Google",'HD-118'!$B$4:$B$18,"D") -> 1595.87 | F50: =E50-D50 -> -6691.67
...

Sheet HD-13
A1: HD-13
A3: CANDIDATE / COMMITTEE | B3: PARTY | C3: PLATFORM | D3: TOTAL SPEND | E3: 05/26/2026 | F3: 06/02/2026 | G3: 06/09/2026 | H3: 06/16/2026 | I3: 06/23/2026 | J3: 06/30/2026 | K3: 07/07/2026 | L3: 07/14/2026 | M3: 07/21/2026 | N3: 07/28/2026 | O3: 08/04/2026
A4: RSLC | B4: R | C4: Google | D4: =SUM(E4:O4) -> 7415.48 | E4: 0 | F4: 597.5 | G4: 716.94 | H4: 869.7 | I4: 951.82 | J4: 747.68 | K4: 913.66 | L4: 877.79 | M4: 971.83 | N4: 768.56 | O4: 0
B5: R | C5: Facebook | D5: =SUM(E5:O5) -> 954.09 | E5: 19.48 | F5: 123.76 | G5: 101.3 | H5: 97.71 | I5: 100.31 | J5: 106.1 | K5: 104.63 | L5: 106.59 | M5: 106.54 | N5: 87.67 | O5: 0
B6: R | C6: RSLC Total | D6: =SUM(E6:O6) -> 8369.57 | E6: =SUM(E4:E5) -> 19.48 | F6: =SUM(F4:F5) -> 721.26 | G6: =SUM(G4:G5) -> 818.24 | H6: =SUM(H4:H5) -> 967.41 | I6: =SUM(I4:I5) -> 1052.13 | J6: =SUM(J4:J5) -> 853.78 | K6: =SUM(K4:K5) -> 1018.29 | L6: =SUM(L4:L5) -> 984.38 | ... O6: =SUM(O4:O5) -> 0
A8: REPUBLICAN PARTY TOTAL | D8: =SUM(E8:O8) -> 8369.57 | E8: =E6 -> 19.48 | F8: =F6 -> 721.26 | G8: =G6 -> 818.24 | H8: =H6 -> 967.41 | I8: =I6 -> 1052.13 | J8: =J6 -> 853.78 | K8: =K6 -> 1018.29 | L8: =L6 -> 984.38 | ... O8: =O6 -> 0
A10: GRAND TOTAL | D10: =SUM(E10:O10) -> 8369.57 | E10: =E8 -> 19.48 | F10: =F8 -> 721.26 | G10: =G8 -> 818.24 | H10: =H8 -> 967.41 | I10: =I8 -> 1052.13 | J10: =J8 -> 853.78 | K10: =K8 -> 1018.29 | L10: =L8 -> 984.38 | ... O10: =O8 -> 0
A12: Report prepared by GPS Impact | Confidential

Sheet HD-16
A1: HD-16
A3: CANDIDATE / COMMITTEE | B3: PARTY | C3: PLATFORM | D3: TOTAL SPEND | E3: 05/26/2026 | F3: 06/02/2026 | G3: 06/09/2026 | H3: 06/16/2026 | I3: 06/23/2026 | J3: 06/30/2026 | K3: 07/07/2026 | L3: 07/14/2026 | M3: 07/21/2026 | N3: 07/28/2026 | O3: 08/04/2026
A4: ROB MATZIE STATE HOUSE | B4: D | C4: Facebook | D4: =SUM(E4:O4) -> 1685.02 | E4: 0 | F4: 0 | G4: 0 | H4: 0 | I4: 0 | J4: 349.72 | K4: 349.74 | L4: 349.8 | M4: 349.84 | N4: 285.92 | O4: 0
B5: D | C5: ROB MATZIE STATE HOUSE Total | D5: =SUM(E5:O5) -> 1685.02 | E5: =SUM(E4:E4) -> 0 | F5: =SUM(F4:F4) -> 0 | G5: =SUM(G4:G4) -> 0 | H5: =SUM(H4:H4) -> 0 | I5: =SUM(I4:I4) -> 0 | J5: =SUM(J4:J4) -> 349.72 | K5: =SUM(K4:K4) -> 349.74 | L5: =SUM(L4:L4) -> 349.8 | ... O5: =SUM(O4:O4) -> 0
A7: COMMONWEALTH MAJORITY | B7: D | C7: CTV | D7: =SUM(E7:O7) -> 510.91 | E7: 0 | F7: 11.06 | G7: 0 | H7: 0 | I7: 61.67 | J7: 88.51 | K7: 91.98 | L7: 86.74 | M7: 94.77 | N7: 76.18 | O7: 0
B8: D | C8: COMMONWEALTH MAJORITY Total | D8: =SUM(E8:O8) -> 510.91 | E8: =SUM(E7:E7) -> 0 | F8: =SUM(F7:F7) -> 11.06 | G8: =SUM(G7:G7) -> 0 | H8: =SUM(H7:H7) -> 0 | I8: =SUM(I7:I7) -> 61.67 | J8: =SUM(J7:J7) -> 88.51 | K8: =SUM(K7:K7) -> 91.98 | L8: =SUM(L7:L7) -> 86.74 | ... O8: =SUM(O7:O7) -> 0
A10: DEMOCRAT PARTY TOTAL | D10: =SUM(E10:O10) -> 2195.93 | E10: =E5+E8 -> 0 | F10: =F5+F8 -> 11.06 | G10: =G5+G8 -> 0 | H10: =H5+H8 -> 0 | I10: =I5+I8 -> 61.67 | J10: =J5+J8 -> 438.23 | K10: =K5+K8 -> 441.72 | L10: =L5+L8 -> 436.54 | ... O10: =O5+O8 -> 0
A12: GRAND TOTAL | D12: =SUM(E12:O12) -> 2195.93 | E12: =E10 -> 0 | F12: =F10 -> 11.06 | G12: =G10 -> 0 | H12: =H10 -> 0 | I12: =I10 -> 61.67 | J12: =J10 -> 438.23 | K12: =K10 -> 441.72 | L12: =L10 -> 436.54 | ... O12: =O10 -> 0
A14: Report prepared by GPS Impact | Confidential

Sheet HD-18
A1: HD-18
A3: CANDIDATE / COMMITTEE | B3: PARTY | C3: PLATFORM | D3: TOTAL SPEND | E3: 05/26/2026 | F3: 06/02/2026 | G3: 06/09/2026 | H3: 06/16/2026 | I3: 06/23/2026 | J3: 06/30/2026 | K3: 07/07/2026 | L3: 07/14/2026 | M3: 07/21/2026 | N3: 07/28/2026 | O3: 08/04/2026
A4: RSLC | B4: R | C4: Google | D4: =SUM(E4:O4) -> 7791.26 | E4: 0 | F4: 614.47 | G4: 1164.55 | H4: 934.99 | I4: 989.41 | J4: 773.49 | K4: 928.81 | L4: 886.92 | M4: 976.29 | N4: 522.33 | O4: 0
B5: R | C5: Facebook | D5: =SUM(E5:O5) -> 955.43 | E5: 21.29 | F5: 140.4 | G5: 107.42 | H5: 102.07 | I5: 92 | J5: 98.38 | K5: 97.19 | L5: 99.05 | M5: 99 | N5: 98.63 | O5: 0
B6: R | C6: RSLC Total | D6: =SUM(E6:O6) -> 8746.69 | E6: =SUM(E4:E5) -> 21.29 | F6: =SUM(F4:F5) -> 754.87 | G6: =SUM(G4:G5) -> 1271.97 | H6: =SUM(H4:H5) -> 1037.06 | I6: =SUM(I4:I5) -> 1081.41 | J6: =SUM(J4:J5) -> 871.87 | K6: =SUM(K4:K5) -> 1026 | L6: =SUM(L4:L5) -> 985.97 | ... O6: =SUM(O4:O5) -> 0
A8: REPUBLICAN PARTY TOTAL | D8: =SUM(E8:O8) -> 8746.69 | E8: =E6 -> 21.29 | F8: =F6 -> 754.87 | G8: =G6 -> 1271.97 | H8: =H6 -> 1037.06 | I8: =I6 -> 1081.41 | J8: =J6 -> 871.87 | K8: =K6 -> 1026 | L8: =L6 -> 985.97 | ... O8: =O6 -> 0
A10: BETTER PA | B10: D | C10: CTV | D10: =SUM(E10:O10) -> 291.25 | E10: 0 | F10: 0 | G10: 0 | H10: 0 | I10: 0 | J10: 0 | K10: 0 | L10: 0 | M10: 131.5 | N10: 159.75 | O10: 0
B11: D | C11: Google | D11: =SUM(E11:O11) -> 1021.56 | E11: 0 | F11: 0 | G11: 0 | H11: 0 | I11: 0 | J11: 0 | K11: 0 | L11: 187.1 | M11: 471.13 | N11: 363.33 | O11: 0
B12: D | C12: Facebook | D12: =SUM(E12:O12) -> 1940.18 | E12: 0 | F12: 0 | G12: 0 | H12: 0 | I12: 0 | J12: 0 | K12: 0 | L12: 450.99 | M12: 848.16 | N12: 641.03 | O12: 0
B13: D | C13: BETTER PA Total | D13: =SUM(E13:O13) -> 3252.99 | E13: =SUM(E10:E12) -> 0 | F13: =SUM(F10:F12) -> 0 | G13: =SUM(G10:G12) -> 0 | H13: =SUM(H10:H12) -> 0 | I13: =SUM(I10:I12) -> 0 | J13: =SUM(J10:J12) -> 0 | K13: =SUM(K10:K12) -> 0 | L13: =SUM(L10:L12) -> 638.09 | ... O13: =SUM(O10:O12) -> 0
A15: DEMOCRAT PARTY TOTAL | D15: =SUM(E15:O15) -> 3252.99 | E15: =E13 -> 0 | F15: =F13 -> 0 | G15: =G13 -> 0 | H15: =H13 -> 0 | I15: =I13 -> 0 | J15: =J13 -> 0 | K15: =K13 -> 0 | L15: =L13 -> 638.09 | ... O15: =O13 -> 0
A17: GRAND TOTAL | D17: =SUM(E17:O17) -> 11999.68 | E17: =E8+E15 -> 21.29 | F17: =F8+F15 -> 754.87 | G17: =G8+G15 -> 1271.97 | H17: =H8+H15 -> 1037.06 | I17: =I8+I15 -> 1081.41 | J17: =J8+J15 -> 871.87 | K17: =K8+K15 -> 1026 | L17: =L8+L15 -> 1624.06 | ... O17: =O8+O15 -> 0
A19: Report prepared by GPS Impact | Confidential

Sheet HD-28
A1: HD-28
A3: CANDIDATE / COMMITTEE | B3: PARTY | C3: PLATFORM | D3: TOTAL SPEND | E3: 05/26/2026 | F3: 06/02/2026 | G3: 06/09/2026 | H3: 06/16/2026 | I3: 06/23/2026 | J3: 06/30/2026 | K3: 07/07/2026 | L3: 07/14/2026 | M3: 07/21/2026 | N3: 07/28/2026 | O3: 08/04/2026
A4: RSLC | B4: R | C4: Google | D4: =SUM(E4:O4) -> 9958.28 | E4: 0 | F4: 770.87 | G4: 1235.03 | H4: 1161.98 | I4: 1248.9 | J4: 978.8 | K4: 1171.36 | L4: 1131.65 | M4: 1249.28 | N4: 1010.41 | O4: 0
B5: R | C5: Facebook | D5: =SUM(E5:O5) -> 1908.57 | E5: 19.78 | F5: 149.7 | G5: 191.68 | H5: 204.68 | I5: 212.42 | J5: 240.22 | K5: 234.61 | L5: 239.09 | M5: 238.97 | N5: 177.42 | O5: 0
B6: R | C6: RSLC Total | D6: =SUM(E6:O6) -> 11866.85 | E6: =SUM(E4:E5) -> 19.78 | F6: =SUM(F4:F5) -> 920.57 | G6: =SUM(G4:G5) -> 1426.71 | H6: =SUM(H4:H5) -> 1366.66 | I6: =SUM(I4:I5) -> 1461.32 | J6: =SUM(J4:J5) -> 1219.02 | K6: =SUM(K4:K5) -> 1405.97 | L6: =SUM(L4:L5) -> 1370.74 | ... O6: =SUM(O4:O5) -> 0
A8: REPUBLICAN PARTY TOTAL | D8: =SUM(E8:O8) -> 11866.85 | E8: =E6 -> 19.78 | F8: =F6 -> 920.57 | G8: =G6 -> 1426.71 | H8: =H6 -> 1366.66 | I8: =I6 -> 1461.32 | J8: =J6 -> 1219.02 | K8: =K6 -> 1405.97 | L8: =L6 -> 1370.74 | ... O8: =O6 -> 0
A10: GRAND TOTAL | D10: =SUM(E10:O10) -> 11866.85 | E10: =E8 -> 19.78 | F10: =F8 -> 920.57 | G10: =G8 -> 1426.71 | H10: =H8 -> 1366.66 | I10: =I8 -> 1461.32 | J10: =J8 -> 1219.02 | K10: =K8 -> 1405.97 | L10: =L8 -> 1370.74 | ... O10: =O8 -> 0
A12: Report prepared by GPS Impact | Confidential

Sheet HD-41
A1: HD-41
A3: CANDIDATE / COMMITTEE | B3: PARTY | C3: PLATFORM | D3: TOTAL SPEND | E3: 05/26/2026 | F3: 06/02/2026 | G3: 06/09/2026 | H3: 06/16/2026 | I3: 06/23/2026 | J3: 06/30/2026 | K3: 07/07/2026 | L3: 07/14/2026 | M3: 07/21/2026 | N3: 07/28/2026 | O3: 08/04/2026
A4: RSLC | B4: R | C4: Google | D4: =SUM(E4:O4) -> 7899.44 | E4: 0 | F4: 687.49 | G4: 1058.58 | H4: 912.23 | I4: 969.94 | J4: 764.08 | K4: 910.99 | L4: 871.89 | M4: 962.41 | N4: 761.83 | O4: 0
B5: R | C5: Facebook | D5: =SUM(E5:O5) -> 901.12 | E5: 19.04 | F5: 178.29 | G5: 88.98 | H5: 91.48 | I5: 90.65 | J5: 92.58 | K5: 89.52 | L5: 91.22 | M5: 91.17 | N5: 68.19 | O5: 0
B6: R | C6: RSLC Total | D6: =SUM(E6:O6) -> 8800.56 | E6: =SUM(E4:E5) -> 19.04 | F6: =SUM(F4:F5) -> 865.78 | G6: =SUM(G4:G5) -> 1147.56 | H6: =SUM(H4:H5) -> 1003.71 | I6: =SUM(I4:I5) -> 1060.59 | J6: =SUM(J4:J5) -> 856.66 | K6: =SUM(K4:K5) -> 1000.51 | L6: =SUM(L4:L5) -> 963.11 | ... O6: =SUM(O4:O5) -> 0
A8: REPUBLICAN PARTY TOTAL | D8: =SUM(E8:O8) -> 8800.56 | E8: =E6 -> 19.04 | F8: =F6 -> 865.78 | G8: =G6 -> 1147.56 | H8: =H6 -> 1003.71 | I8: =I6 -> 1060.59 | J8: =J6 -> 856.66 | K8: =K6 -> 1000.51 | L8: =L6 -> 963.11 | ... O8: =O6 -> 0
A10: GRAND TOTAL | D10: =SUM(E10:O10) -> 8800.56 | E10: =E8 -> 19.04 | F10: =F8 -> 865.78 | G10: =G8 -> 1147.56 | H10: =H8 -> 1003.71 | I10: =I8 -> 1060.59 | J10: =J8 -> 856.66 | K10: =K8 -> 1000.51 | L10: =L8 -> 963.11 | ... O10: =O8 -> 0
A12: Report prepared by GPS Impact | Confidential

Sheet HD-44
A1: HD-44
A3: CANDIDATE / COMMITTEE | B3: PARTY | C3: PLATFORM | D3: TOTAL SPEND | E3: 05/26/2026 | F3: 06/02/2026 | G3: 06/09/2026 | H3: 06/16/2026 | I3: 06/23/2026 | J3: 06/30/2026 | K3: 07/07/2026 | L3: 07/14/2026 | M3: 07/21/2026 | N3: 07/28/2026 | O3: 08/04/2026
A4: RSLC | B4: R | C4: Google | D4: =SUM(E4:O4) -> 9522.05 | E4: 0 | F4: 583.55 | G4: 1048.65 | H4: 1103.33 | I4: 1157.28 | J4: 899.34 | K4: 1085.85 | L4: 1046.72 | M4: 1151.18 | N4: 966.07 | O4: 480.08
B5: R | C5: Facebook | D5: =SUM(E5:O5) -> 1592.3 | E5: 25.3 | F5: 267.66 | G5: 180.88 | H5: 167.3 | I5: 169.56 | J5: 168.34 | K5: 163.43 | L5: 166.53 | M5: 166.44 | N5: 116.86 | O5: 0
B6: R | C6: RSLC Total | D6: =SUM(E6:O6) -> 11114.35 | E6: =SUM(E4:E5) -> 25.3 | F6: =SUM(F4:F5) -> 851.21 | G6: =SUM(G4:G5) -> 1229.53 | H6: =SUM(H4:H5) -> 1270.63 | I6: =SUM(I4:I5) -> 1326.84 | J6: =SUM(J4:J5) -> 1067.68 | K6: =SUM(K4:K5) -> 1249.28 | L6: =SUM(L4:L5) -> 1213.25 | ... O6: =SUM(O4:O5) -> 480.08
A8: REPUBLICAN PARTY TOTAL | D8: =SUM(E8:O8) -> 11114.35 | E8: =E6 -> 25.3 | F8: =F6 -> 851.21 | G8: =G6 -> 1229.53 | H8: =H6 -> 1270.63 | I8: =I6 -> 1326.84 | J8: =J6 -> 1067.68 | K8: =K6 -> 1249.28 | L8: =L6 -> 1213.25 | ... O8: =O6 -> 480.08
A10: BETTER PA | B10: D | C10: CTV | D10: =SUM(E10:O10) -> 985.79 | E10: 0 | F10: 0 | G10: 0 | H10: 0 | I10: 0 | J10: 0 | K10: 0 | L10: 0 | M10: 427.44 | N10: 558.35 | O10: 0
B11: D | C11: Google | D11: =SUM(E11:O11) -> 3504.84 | E11: 0 | F11: 0 | G11: 0 | H11: 0 | I11: 0 | J11: 0 | K11: 0 | L11: 806.58 | M11: 1505.55 | N11: 1192.71 | O11: 0
B12: D | C12: Facebook | D12: =SUM(E12:O12) -> 2100.69 | E12: 0 | F12: 0 | G12: 0 | H12: 0 | I12: 0 | J12: 0 | K12: 0 | L12: 492.55 | M12: 915.9 | N12: 692.24 | O12: 0
B13: D | C13: BETTER PA Total | D13: =SUM(E13:O13) -> 6591.32 | E13: =SUM(E10:E12) -> 0 | F13: =SUM(F10:F12) -> 0 | G13: =SUM(G10:G12) -> 0 | H13: =SUM(H10:H12) -> 0 | I13: =SUM(I10:I12) -> 0 | J13: =SUM(J10:J12) -> 0 | K13: =SUM(K10:K12) -> 0 | L13: =SUM(L10:L12) -> 1299.13 | ... O13: =SUM(O10:O12) -> 0
A15: HADLEY HAAS STATE HOUSE | B15: D | C15: Facebook | D15: =SUM(E15:O15) -> 2109.88 | E15: 0 | F15: 0 | G15: 0 | H15: 0 | I15: 0 | J15: 400.81 | K15: 454.81 | L15: 457.8 | M15: 507.79 | N15: 288.67 | O15: 0
B16: D | C16: HADLEY HAAS STATE HOUSE Total | D16: =SUM(E16:O16) -> 2109.88 | E16: =SUM(E15:E15) -> 0 | F16: =SUM(F15:F15) -> 0 | G16: =SUM(G15:G15) -> 0 | H16: =SUM(H15:H15) -> 0 | I16: =SUM(I15:I15) -> 0 | J16: =SUM(J15:J15) -> 400.81 | K16: =SUM(K15:K15) -> 454.81 | L16: =SUM(L15:L15) -> 457.8 | ... O16: =SUM(O15:O15) -> 0
A18: FAIR DEMOCRACY | B18: D | C18: Facebook | D18: =SUM(E18:O18) -> 838.22 | E18: 33.16 | F18: 141.31 | G18: 125.89 | H18: 125.98 | I18: 129.69 | J18: 132.15 | K18: 125.19 | L18: 24.85 | M18: 0 | N18: 0 | O18: 0
B19: D | C19: FAIR DEMOCRACY Total | D19: =SUM(E19:O19) -> 838.22 | E19: =SUM(E18:E18) -> 33.16 | F19: =SUM(F18:F18) -> 141.31 | G19: =SUM(G18:G18) -> 125.89 | H19: =SUM(H18:H18) -> 125.98 | I19: =SUM(I18:I18) -> 129.69 | J19: =SUM(J18:J18) -> 132.15 | K19: =SUM(K18:K18) -> 125.19 | L19: =SUM(L18:L18) -> 24.85 | ... O19: =SUM(O18:O18) -> 0
A21: DEMOCRAT PARTY TOTAL | D21: =SUM(E21:O21) -> 9539.42 | E21: =E13+E16+E19 -> 33.16 | F21: =F13+F16+F19 -> 141.31 | G21: =G13+G16+G19 -> 125.89 | H21: =H13+H16+H19 -> 125.98 | I21: =I13+I16+I19 -> 129.69 | J21: =J13+J16+J19 -> 532.96 | K21: =K13+K16+K19 -> 580 | L21: =L13+L16+L19 -> 1781.78 | ... O21: =O13+O16+O19 -> 0
A23: GRAND TOTAL | D23: =SUM(E23:O23) -> 20653.77 | E23: =E8+E21 -> 58.46 | F23: =F8+F21 -> 992.52 | G23: =G8+G21 -> 1355.42 | H23: =H8+H21 -> 1396.61 | I23: =I8+I21 -> 1456.53 | J23: =J8+J21 -> 1600.64 | K23: =K8+K21 -> 1829.28 | L23: =L8+L21 -> 2995.03 | ... O23: =O8+O21 -> 480.08
A25: Report prepared by GPS Impact | Confidential

Sheet HD-46
A1: HD-46
A3: CANDIDATE / COMMITTEE | B3: PARTY | C3: PLATFORM | D3: TOTAL SPEND | E3: 05/26/2026 | F3: 06/02/2026 | G3: 06/09/2026 | H3: 06/16/2026 | I3: 06/23/2026 | J3: 06/30/2026 | K3: 07/07/2026 | L3: 07/14/2026 | M3: 07/21/2026 | N3: 07/28/2026 | O3: 08/04/2026
A4: JASON ORTITAY STATE HOUSE | B4: R | C4: Google | D4: =SUM(E4:O4) -> 600 | E4: 0 | F4: 0 | G4: 0 | H4: 0 | I4: 0 | J4: 0 | K4: 0 | L4: 0 | M4: 0 | N4: 600 | O4: 0
B5: R | C5: Facebook | D5: =SUM(E5:O5) -> 1140.3 | E5: 0 | F5: 0 | G5: 0 | H5: 0 | I5: 0 | J5: 0 | K5: 49.99 | L5: 401.94 | M5: 400.94 | N5: 287.43 | O5: 0
B6: R | C6: JASON ORTITAY STATE HOUSE Total | D6: =SUM(E6:O6) -> 1740.3 | E6: =SUM(E4:E5) -> 0 | F6: =SUM(F4:F5) -> 0 | G6: =SUM(G4:G5) -> 0 | H6: =SUM(H4:H5) -> 0 | I6: =SUM(I4:I5) -> 0 | J6: =SUM(J4:J5) -> 0 | K6: =SUM(K4:K5) -> 49.99 | L6: =SUM(L4:L5) -> 401.94 | ... O6: =SUM(O4:O5) -> 0
A8: REPUBLICAN PARTY TOTAL | D8: =SUM(E8:O8) -> 1740.3 | E8: =E6 -> 0 | F8: =F6 -> 0 | G8: =G6 -> 0 | H8: =H6 -> 0 | I8: =I6 -> 0 | J8: =J6 -> 0 | K8: =K6 -> 49.99 | L8: =L6 -> 401.94 | ... O8: =O6 -> 0
A10: GRAND TOTAL | D10: =SUM(E10:O10) -> 1740.3 | E10: =E8 -> 0 | F10: =F8 -> 0 | G10: =G8 -> 0 | H10: =H8 -> 0 | I10: =I8 -> 0 | J10: =J8 -> 0 | K10: =K8 -> 49.99 | L10: =L8 -> 401.94 | ... O10: =O8 -> 0
A12: Report prepared by GPS Impact | Confidential

Sheet HD-72
A1: HD-72
A3: CANDIDATE / COMMITTEE | B3: PARTY | C3: PLATFORM | D3: TOTAL SPEND | E3: 05/26/2026 | F3: 06/02/2026 | G3: 06/09/2026 | H3: 06/16/2026 | I3: 06/23/2026 | J3: 06/30/2026 | K3: 07/07/2026 | L3: 07/14/2026 | M3: 07/21/2026 | N3: 07/28/2026 | O3: 08/04/2026
A4: RSLC | B4: R | C4: Google | D4: =SUM(E4:O4) -> 19315.89 | E4: 0 | F4: 627.13 | G4: 1754.4 | H4: 5372.51 | I4: 4436.64 | J4: 1644.58 | K4: 1632.44 | L4: 1468.88 | M4: 1553.29 | N4: 826.02 | O4: 0
B5: R | C5: Facebook | D5: =SUM(E5:O5) -> 1093.71 | E5: 2.91 | F5: 55.18 | G5: 131.95 | H5: 144.02 | I5: 140.05 | J5: 137.8 | K5: 133.25 | L5: 135.77 | M5: 135.69 | N5: 77.09 | O5: 0
B6: R | C6: RSLC Total | D6: =SUM(E6:O6) -> 20409.6 | E6: =SUM(E4:E5) -> 2.91 | F6: =SUM(F4:F5) -> 682.31 | G6: =SUM(G4:G5) -> 1886.35 | H6: =SUM(H4:H5) -> 5516.53 | I6: =SUM(I4:I5) -> 4576.69 | J6: =SUM(J4:J5) -> 1782.38 | K6: =SUM(K4:K5) -> 1765.69 | L6: =SUM(L4:L5) -> 1604.65 | ... O6: =SUM(O4:O5) -> 0
A8: CITIZENS ALLIANCE PA | B8: R | C8: Facebook | D8: =SUM(E8:O8) -> 562.47 | E8: 0 | F8: 0 | G8: 0 | H8: 0 | I8: 0 | J8: 160.68 | K8: 323.7 | L8: 78.09 | M8: 0 | N8: 0 | O8: 0
B9: R | C9: CITIZENS ALLIANCE PA Total | D9: =SUM(E9:O9) -> 562.47 | E9: =SUM(E8:E8) -> 0 | F9: =SUM(F8:F8) -> 0 | G9: =SUM(G8:G8) -> 0 | H9: =SUM(H8:H8) -> 0 | I9: =SUM(I8:I8) -> 0 | J9: =SUM(J8:J8) -> 160.68 | K9: =SUM(K8:K8) -> 323.7 | L9: =SUM(L8:L8) -> 78.09 | ... O9: =SUM(O8:O8) -> 0
A11: REPUBLICAN PARTY TOTAL | D11: =SUM(E11:O11) -> 20972.07 | E11: =E6+E9 -> 2.91 | F11: =F6+F9 -> 682.31 | G11: =G6+G9 -> 1886.35 | H11: =H6+H9 -> 5516.53 | I11: =I6+I9 -> 4576.69 | J11: =J6+J9 -> 1943.06 | K11: =K6+K9 -> 2089.39 | L11: =L6+L9 -> 1682.74 | ... O11: =O6+O9 -> 0
A13: FRANK BURNS STATE HOUSE | B13: D | C13: CTV | D13: =SUM(E13:O13) -> 66444.37 | E13: 0 | F13: 0 | G13: 0 | H13: 39.41 | I13: 1991.04 | J13: 9659.66 | K13: 10582.19 | L13: 11032.46 | M13: 18162.59 | N13: 14977.02 | O13: 0
B14: D | C14: Google | D14: =SUM(E14:O14) -> 2823.41 | E14: 0 | F14: 0 | G14: 0 | H14: 0 | I14: 0 | J14: 0 | K14: 172.5 | L14: 270.88 | M14: 1141.57 | N14: 1238.46 | O14: 0
B15: D | C15: Facebook | D15: =SUM(E15:O15) -> 9468.89 | E15: 49.95 | F15: 649.43 | G15: 673.51 | H15: 607.75 | I15: 1157.27 | J15: 1718.52 | K15: 1439.44 | L15: 1158.05 | M15: 1199.26 | N15: 815.71 | O15: 0
B16: D | C16: FRANK BURNS STATE HOUSE Total | D16: =SUM(E16:O16) -> 78736.67 | E16: =SUM(E13:E15) -> 49.95 | F16: =SUM(F13:F15) -> 649.43 | G16: =SUM(G13:G15) -> 673.51 | H16: =SUM(H13:H15) -> 647.16 | I16: =SUM(I13:I15) -> 3148.31 | J16: =SUM(J13:J15) -> 11378.18 | K16: =SUM(K13:K15) -> 12194.13 | L16: =SUM(L13:L15) -> 12461.39 | ... O16: =SUM(O13:O15) -> 0
A18: COMMONWEALTH MAJORITY | B18: D | C18: CTV | D18: =SUM(E18:O18) -> 1229.26 | E18: 0 | F18: 8.98 | G18: 113.98 | H18: 221.59 | I18: 132.31 | J18: 172.18 | K18: 156.78 | L18: 129.14 | M18: 157.48 | N18: 136.82 | O18: 0
B19: D | C19: COMMONWEALTH MAJORITY Total | D19: =SUM(E19:O19) -> 1229.26 | E19: =SUM(E18:E18) -> 0 | F19: =SUM(F18:F18) -> 8.98 | G19: =SUM(G18:G18) -> 113.98 | H19: =SUM(H18:H18) -> 221.59 | I19: =SUM(I18:I18) -> 132.31 | J19: =SUM(J18:J18) -> 172.18 | K19: =SUM(K18:K18) -> 156.78 | L19: =SUM(L18:L18) -> 129.14 | ... O19: =SUM(O18:O18) -> 0
A21: NEA | B21: D | C21: Facebook | D21: =SUM(E21:O21) -> 178.83 | E21: 0 | F21: 0 | G21: 0 | H21: 0 | I21: 0 | J21: 127.61 | K21: 51.22 | L21: 0 | M21: 0 | N21: 0 | O21: 0
B22: D | C22: NEA Total | D22: =SUM(E22:O22) -> 178.83 | E22: =SUM(E21:E21) -> 0 | F22: =SUM(F21:F21) -> 0 | G22: =SUM(G21:G21) -> 0 | H22: =SUM(H21:H21) -> 0 | I22: =SUM(I21:I21) -> 0 | J22: =SUM(J21:J21) -> 127.61 | K22: =SUM(K21:K21) -> 51.22 | L22: =SUM(L21:L21) -> 0 | ... O22: =SUM(O21:O21) -> 0
A24: DEMOCRAT PARTY TOTAL | D24: =SUM(E24:O24) -> 80144.76 | E24: =E16+E19+E22 -> 49.95 | F24: =F16+F19+F22 -> 658.41 | G24: =G16+G19+G22 -> 787.49 | H24: =H16+H19+H22 -> 868.75 | I24: =I16+I19+I22 -> 3280.62 | J24: =J16+J19+J22 -> 11677.97 | K24: =K16+K19+K22 -> 12402.13 | L24: =L16+L19+L22 -> 12590.53 | ... O24: =O16+O19+O22 -> 0
A26: GRAND TOTAL | D26: =SUM(E26:O26) -> 101116.83 | E26: =E11+E24 -> 52.86 | F26: =F11+F24 -> 1340.72 | G26: =G11+G24 -> 2673.84 | H26: =H11+H24 -> 6385.28 | I26: =I11+I24 -> 7857.31 | J26: =J11+J24 -> 13621.03 | K26: =K11+K24 -> 14491.52 | L26: =L11+L24 -> 14273.27 | ... O26: =O11+O24 -> 0
A28: Report prepared by GPS Impact | Confidential

Sheet HD-88
A1: HD-88
A3: CANDIDATE / COMMITTEE | B3: PARTY | C3: PLATFORM | D3: TOTAL SPEND | E3: 05/26/2026 | F3: 06/02/2026 | G3: 06/09/2026 | H3: 06/16/2026 | I3: 06/23/2026 | J3: 06/30/2026 | K3: 07/07/2026 | L3: 07/14/2026 | M3: 07/21/2026 | N3: 07/28/2026 | O3: 08/04/2026
A4: RSLC | B4: R | C4: Google | D4: =SUM(E4:O4) -> 8032.72 | E4: 0 | F4: 537.47 | G4: 1235.26 | H4: 966.33 | I4: 1000.57 | J4: 775.06 | K4: 913.52 | L4: 875.66 | M4: 960.42 | N4: 768.43 | O4: 0
B5: R | C5: Facebook | D5: =SUM(E5:O5) -> 672.68 | E5: 2.18 | F5: 34.52 | G5: 83.15 | H5: 86.45 | I5: 86.45 | J5: 85.26 | K5: 82.63 | L5: 84.18 | M5: 84.11 | N5: 43.75 | O5: 0
B6: R | C6: RSLC Total | D6: =SUM(E6:O6) -> 8705.4 | E6: =SUM(E4:E5) -> 2.18 | F6: =SUM(F4:F5) -> 571.99 | G6: =SUM(G4:G5) -> 1318.41 | H6: =SUM(H4:H5) -> 1052.78 | I6: =SUM(I4:I5) -> 1087.02 | J6: =SUM(J4:J5) -> 860.32 | K6: =SUM(K4:K5) -> 996.15 | L6: =SUM(L4:L5) -> 959.84 | ... O6: =SUM(O4:O5) -> 0
A8: REPUBLICAN PARTY TOTAL | D8: =SUM(E8:O8) -> 8705.4 | E8: =E6 -> 2.18 | F8: =F6 -> 571.99 | G8: =G6 -> 1318.41 | H8: =H6 -> 1052.78 | I8: =I6 -> 1087.02 | J8: =J6 -> 860.32 | K8: =K6 -> 996.15 | L8: =L6 -> 959.84 | ... O8: =O6 -> 0
A10: SARA AGERTON STATE HOUSE | B10: D | C10: Facebook | D10: =SUM(E10:O10) -> 3028.6 | E10: 0 | F10: 0 | G10: 0 | H10: 0 | I10: 0 | J10: 522.82 | K10: 688.86 | L10: 679.88 | M10: 735.92 | N10: 401.12 | O10: 0
B11: D | C11: SARA AGERTON STATE HOUSE Total | D11: =SUM(E11:O11) -> 3028.6 | E11: =SUM(E10:E10) -> 0 | F11: =SUM(F10:F10) -> 0 | G11: =SUM(G10:G10) -> 0 | H11: =SUM(H10:H10) -> 0 | I11: =SUM(I10:I10) -> 0 | J11: =SUM(J10:J10) -> 522.82 | K11: =SUM(K10:K10) -> 688.86 | L11: =SUM(L10:L10) -> 679.88 | ... O11: =SUM(O10:O10) -> 0
A13: DEMOCRAT PARTY TOTAL | D13: =SUM(E13:O13) -> 3028.6 | E13: =E11 -> 0 | F13: =F11 -> 0 | G13: =G11 -> 0 | H13: =H11 -> 0 | I13: =I11 -> 0 | J13: =J11 -> 522.82 | K13: =K11 -> 688.86 | L13: =L11 -> 679.88 | ... O13: =O11 -> 0
A15: GRAND TOTAL | D15: =SUM(E15:O15) -> 11734 | E15: =E8+E13 -> 2.18 | F15: =F8+F13 -> 571.99 | G15: =G8+G13 -> 1318.41 | H15: =H8+H13 -> 1052.78 | I15: =I8+I13 -> 1087.02 | J15: =J8+J13 -> 1383.14 | K15: =K8+K13 -> 1685.01 | L15: =L8+L13 -> 1639.72 | ... O15: =O8+O13 -> 0
A17: Report prepared by GPS Impact | Confidential

Sheet HD-118
A1: HD-118
A3: CANDIDATE / COMMITTEE | B3: PARTY | C3: PLATFORM | D3: TOTAL SPEND | E3: 05/26/2026 | F3: 06/02/2026 | G3: 06/09/2026 | H3: 06/16/2026 | I3: 06/23/2026 | J3: 06/30/2026 | K3: 07/07/2026 | L3: 07/14/2026 | M3: 07/21/2026 | N3: 07/28/2026 | O3: 08/04/2026
A4: RSLC | B4: R | C4: Google | D4: =SUM(E4:O4) -> 8287.54 | E4: 0 | F4: 538.49 | G4: 817.59 | H4: 1100.71 | I4: 1205.71 | J4: 844.57 | K4: 980 | L4: 922.89 | M4: 1005.1 | N4: 872.48 | O4: 0
B5: R | C5: Facebook | D5: =SUM(E5:O5) -> 950.53 | E5: 14.09 | F5: 161.08 | G5: 114.69 | H5: 84.49 | I5: 96.57 | J5: 95.27 | K5: 92.07 | L5: 93.84 | M5: 93.79 | N5: 104.64 | O5: 0
B6: R | C6: RSLC Total | D6: =SUM(E6:O6) -> 9238.07 | E6: =SUM(E4:E5) -> 14.09 | F6: =SUM(F4:F5) -> 699.57 | G6: =SUM(G4:G5) -> 932.28 | H6: =SUM(H4:H5) -> 1185.2 | I6: =SUM(I4:I5) -> 1302.28 | J6: =SUM(J4:J5) -> 939.84 | K6: =SUM(K4:K5) -> 1072.07 | L6: =SUM(L4:L5) -> 1016.73 | ... O6: =SUM(O4:O5) -> 0
A8: REPUBLICAN PARTY TOTAL | D8: =SUM(E8:O8) -> 9238.07 | E8: =E6 -> 14.09 | F8: =F6 -> 699.57 | G8: =G6 -> 932.28 | H8: =H6 -> 1185.2 | I8: =I6 -> 1302.28 | J8: =J6 -> 939.84 | K8: =K6 -> 1072.07 | L8: =L6 -> 1016.73 | ... O8: =O6 -> 0
A10: COMMONWEALTH MAJORITY | B10: D | C10: CTV | D10: =SUM(E10:O10) -> 2510.2 | E10: 0 | F10: 55.22 | G10: 224.26 | H10: 321.24 | I10: 317.95 | J10: 325 | K10: 310.46 | L10: 312.96 | M10: 347.3 | N10: 295.81 | O10: 0
B11: D | C11: COMMONWEALTH MAJORITY Total | D11: =SUM(E11:O11) -> 2510.2 | E11: =SUM(E10:E10) -> 0 | F11: =SUM(F10:F10) -> 55.22 | G11: =SUM(G10:G10) -> 224.26 | H11: =SUM(H10:H10) -> 321.24 | I11: =SUM(I10:I10) -> 317.95 | J11: =SUM(J10:J10) -> 325 | K11: =SUM(K10:K10) -> 310.46 | L11: =SUM(L10:L10) -> 312.96 | ... O11: =SUM(O10:O10) -> 0
A13: JIM HADDOCK STATE HOUSE | B13: D | C13: Google | D13: =SUM(E13:O13) -> 1595.87 | E13: 0 | F13: 0 | G13: 0 | H13: 0 | I13: 0 | J13: 0 | K13: 0 | L13: 320 | M13: 680 | N13: 566.67 | O13: 29.2
B14: D | C14: JIM HADDOCK STATE HOUSE Total | D14: =SUM(E14:O14) -> 1595.87 | E14: =SUM(E13:E13) -> 0 | F14: =SUM(F13:F13) -> 0 | G14: =SUM(G13:G13) -> 0 | H14: =SUM(H13:H13) -> 0 | I14: =SUM(I13:I13) -> 0 | J14: =SUM(J13:J13) -> 0 | K14: =SUM(K13:K13) -> 0 | L14: =SUM(L13:L13) -> 320 | ... O14: =SUM(O13:O13) -> 29.2
A16: DEMOCRAT PARTY TOTAL | D16: =SUM(E16:O16) -> 4106.07 | E16: =E11+E14 -> 0 | F16: =F11+F14 -> 55.22 | G16: =G11+G14 -> 224.26 | H16: =H11+H14 -> 321.24 | I16: =I11+I14 -> 317.95 | J16: =J11+J14 -> 325 | K16: =K11+K14 -> 310.46 | L16: =L11+L14 -> 632.96 | ... O16: =O11+O14 -> 29.2
A18: GRAND TOTAL | D18: =SUM(E18:O18) -> 13344.14 | E18: =E8+E16 -> 14.09 | F18: =F8+F16 -> 754.79 | G18: =G8+G16 -> 1156.54 | H18: =H8+H16 -> 1506.44 | I18: =I8+I16 -> 1620.23 | J18: =J8+J16 -> 1264.84 | K18: =K8+K16 -> 1382.53 | L18: =L8+L16 -> 1649.69 | ... O18: =O8+O16 -> 29.2
A20: Report prepared by GPS Impact | Confidential

Sheet HD-121
A1: HD-121
A3: CANDIDATE / COMMITTEE | B3: PARTY | C3: PLATFORM | D3: TOTAL SPEND | E3: 05/26/2026 | F3: 06/02/2026 | G3: 06/09/2026 | H3: 06/16/2026 | I3: 06/23/2026 | J3: 06/30/2026 | K3: 07/07/2026 | L3: 07/14/2026 | M3: 07/21/2026 | N3: 07/28/2026 | O3: 08/04/2026
A4: JESSICA MCCLAY STATE HOUSE | B4: D | C4: CTV | D4: =SUM(E4:O4) -> 7904.74 | E4: 0 | F4: 0 | G4: 0 | H4: 0 | I4: 0 | J4: 0 | K4: 0 | L4: 7577.94 | M4: 307.13 | N4: 19.67 | O4: 0
B5: D | C5: Google | D5: =SUM(E5:O5) -> 15100 | E5: 0 | F5: 0 | G5: 0 | H5: 0 | I5: 0 | J5: 0 | K5: 100 | L5: 5784.75 | M5: 5215.25 | N5: 3790 | O5: 210
B6: D | C6: JESSICA MCCLAY STATE HOUSE Total | D6: =SUM(E6:O6) -> 23004.74 | E6: =SUM(E4:E5) -> 0 | F6: =SUM(F4:F5) -> 0 | G6: =SUM(G4:G5) -> 0 | H6: =SUM(H4:H5) -> 0 | I6: =SUM(I4:I5) -> 0 | J6: =SUM(J4:J5) -> 0 | K6: =SUM(K4:K5) -> 100 | L6: =SUM(L4:L5) -> 13362.69 | ... O6: =SUM(O4:O5) -> 210
A8: DEMOCRAT PARTY TOTAL | D8: =SUM(E8:O8) -> 23004.74 | E8: =E6 -> 0 | F8: =F6 -> 0 | G8: =G6 -> 0 | H8: =H6 -> 0 | I8: =I6 -> 0 | J8: =J6 -> 0 | K8: =K6 -> 100 | L8: =L6 -> 13362.69 | ... O8: =O6 -> 210
A10: GRAND TOTAL | D10: =SUM(E10:O10) -> 23004.74 | E10: =E8 -> 0 | F10: =F8 -> 0 | G10: =G8 -> 0 | H10: =H8 -> 0 | I10: =I8 -> 0 | J10: =J8 -> 0 | K10: =K8 -> 100 | L10: =L8 -> 13362.69 | ... O10: =O8 -> 210
A12: Report prepared by GPS Impact | Confidential

Sheet HD-137
A1: HD-137
A3: CANDIDATE / COMMITTEE | B3: PARTY | C3: PLATFORM | D3: TOTAL SPEND | E3: 05/26/2026 | F3: 06/02/2026 | G3: 06/09/2026 | H3: 06/16/2026 | I3: 06/23/2026 | J3: 06/30/2026 | K3: 07/07/2026 | L3: 07/14/2026 | M3: 07/21/2026 | N3: 07/28/2026 | O3: 08/04/2026
A4: RSLC | B4: R | C4: Google | D4: =SUM(E4:O4) -> 11017.23 | E4: 0 | F4: 605.98 | G4: 1323.63 | H4: 1266.75 | I4: 1377.43 | J4: 1076.89 | K4: 1304.89 | L4: 1259.93 | M4: 1392.91 | N4: 1187.34 | O4: 221.48
B5: R | C5: Facebook | D5: =SUM(E5:O5) -> 1356.85 | E5: 18.71 | F5: 140.26 | G5: 151.12 | H5: 151.49 | I5: 158.5 | J5: 153.22 | K5: 148.28 | L5: 151.11 | M5: 151.01 | N5: 133.15 | O5: 0
B6: R | C6: RSLC Total | D6: =SUM(E6:O6) -> 12374.08 | E6: =SUM(E4:E5) -> 18.71 | F6: =SUM(F4:F5) -> 746.24 | G6: =SUM(G4:G5) -> 1474.75 | H6: =SUM(H4:H5) -> 1418.24 | I6: =SUM(I4:I5) -> 1535.93 | J6: =SUM(J4:J5) -> 1230.11 | K6: =SUM(K4:K5) -> 1453.17 | L6: =SUM(L4:L5) -> 1411.04 | ... O6: =SUM(O4:O5) -> 221.48
A8: JOE EMRICK STATE HOUSE | B8: R | C8: Facebook | D8: =SUM(E8:O8) -> 2130.56 | E8: 0 | F8: 0 | G8: 0 | H8: 0 | I8: 0 | J8: 0 | K8: 0 | L8: 0 | M8: 1271.93 | N8: 858.63 | O8: 0
B9: R | C9: JOE EMRICK STATE HOUSE Total | D9: =SUM(E9:O9) -> 2130.56 | E9: =SUM(E8:E8) -> 0 | F9: =SUM(F8:F8) -> 0 | G9: =SUM(G8:G8) -> 0 | H9: =SUM(H8:H8) -> 0 | I9: =SUM(I8:I8) -> 0 | J9: =SUM(J8:J8) -> 0 | K9: =SUM(K8:K8) -> 0 | L9: =SUM(L8:L8) -> 0 | ... O9: =SUM(O8:O8) -> 0
A11: REPUBLICAN PARTY TOTAL | D11: =SUM(E11:O11) -> 14504.64 | E11: =E6+E9 -> 18.71 | F11: =F6+F9 -> 746.24 | G11: =G6+G9 -> 1474.75 | H11: =H6+H9 -> 1418.24 | I11: =I6+I9 -> 1535.93 | J11: =J6+J9 -> 1230.11 | K11: =K6+K9 -> 1453.17 | L11: =L6+L9 -> 1411.04 | ... O11: =O6+O9 -> 221.48
A13: BETTER PA | B13: D | C13: CTV | D13: =SUM(E13:O13) -> 53763.57 | E13: 0 | F13: 0 | G13: 0 | H13: 0 | I13: 0 | J13: 0 | K13: 0 | L13: 0 | M13: 26295.94 | N13: 27467.63 | O13: 0
B14: D | C14: Google | D14: =SUM(E14:O14) -> 7824.55 | E14: 0 | F14: 0 | G14: 0 | H14: 0 | I14: 0 | J14: 0 | K14: 0 | L14: 1329.74 | M14: 3554.37 | N14: 2940.44 | O14: 0
B15: D | C15: Facebook | D15: =SUM(E15:O15) -> 2095.91 | E15: 0 | F15: 0 | G15: 0 | H15: 0 | I15: 0 | J15: 0 | K15: 0 | L15: 487.53 | M15: 916.08 | N15: 692.3 | O15: 0
B16: D | C16: BETTER PA Total | D16: =SUM(E16:O16) -> 63684.03 | E16: =SUM(E13:E15) -> 0 | F16: =SUM(F13:F15) -> 0 | G16: =SUM(G13:G15) -> 0 | H16: =SUM(H13:H15) -> 0 | I16: =SUM(I13:I15) -> 0 | J16: =SUM(J13:J15) -> 0 | K16: =SUM(K13:K15) -> 0 | L16: =SUM(L13:L15) -> 1817.27 | ... O16: =SUM(O13:O15) -> 0
A18: FAIR DEMOCRACY | B18: D | C18: Facebook | D18: =SUM(E18:O18) -> 782.11 | E18: 13.48 | F18: 106.28 | G18: 128.5 | H18: 128.28 | I18: 132.05 | J18: 134.61 | K18: 127.52 | L18: 11.39 | M18: 0 | N18: 0 | O18: 0
B19: D | C19: FAIR DEMOCRACY Total | D19: =SUM(E19:O19) -> 782.11 | E19: =SUM(E18:E18) -> 13.48 | F19: =SUM(F18:F18) -> 106.28 | G19: =SUM(G18:G18) -> 128.5 | H19: =SUM(H18:H18) -> 128.28 | I19: =SUM(I18:I18) -> 132.05 | J19: =SUM(J18:J18) -> 134.61 | K19: =SUM(K18:K18) -> 127.52 | L19: =SUM(L18:L18) -> 11.39 | ... O19: =SUM(O18:O18) -> 0
A21: DEMOCRAT PARTY TOTAL | D21: =SUM(E21:O21) -> 64466.14 | E21: =E16+E19 -> 13.48 | F21: =F16+F19 -> 106.28 | G21: =G16+G19 -> 128.5 | H21: =H16+H19 -> 128.28 | I21: =I16+I19 -> 132.05 | J21: =J16+J19 -> 134.61 | K21: =K16+K19 -> 127.52 | L21: =L16+L19 -> 1828.66 | ... O21: =O16+O19 -> 0
A23: GRAND TOTAL | D23: =SUM(E23:O23) -> 78970.78 | E23: =E11+E21 -> 32.19 | F23: =F11+F21 -> 852.52 | G23: =G11+G21 -> 1603.25 | H23: =H11+H21 -> 1546.52 | I23: =I11+I21 -> 1667.98 | J23: =J11+J21 -> 1364.72 | K23: =K11+K21 -> 1580.69 | L23: =L11+L21 -> 3239.7 | ... O23: =O11+O21 -> 221.48
A25: Report prepared by GPS Impact | Confidential

Sheet HD-142
A1: HD-142
A3: CANDIDATE / COMMITTEE | B3: PARTY | C3: PLATFORM | D3: TOTAL SPEND | E3: 05/26/2026 | F3: 06/02/2026 | G3: 06/09/2026 | H3: 06/16/2026 | I3: 06/23/2026 | J3: 06/30/2026 | K3: 07/07/2026 | L3: 07/14/2026 | M3: 07/21/2026 | N3: 07/28/2026 | O3: 08/04/2026
A4: RSLC | B4: R | C4: Google | D4: =SUM(E4:O4) -> 9083.11 | E4: 0 | F4: 612.09 | G4: 1201.01 | H4: 1067.63 | I4: 1136.89 | J4: 890.08 | K4: 1101.61 | L4: 1058.19 | M4: 1164.7 | N4: 625.74 | O4: 225.17
B5: R | C5: Facebook | D5: =SUM(E5:O5) -> 1153.65 | E5: 3.62 | F5: 57.74 | G5: 135.76 | H5: 135.63 | I5: 136.3 | J5: 153.64 | K5: 149.02 | L5: 151.86 | M5: 151.79 | N5: 78.29 | O5: 0
B6: R | C6: RSLC Total | D6: =SUM(E6:O6) -> 10236.76 | E6: =SUM(E4:E5) -> 3.62 | F6: =SUM(F4:F5) -> 669.83 | G6: =SUM(G4:G5) -> 1336.77 | H6: =SUM(H4:H5) -> 1203.26 | I6: =SUM(I4:I5) -> 1273.19 | J6: =SUM(J4:J5) -> 1043.72 | K6: =SUM(K4:K5) -> 1250.63 | L6: =SUM(L4:L5) -> 1210.05 | ... O6: =SUM(O4:O5) -> 225.17
A8: REPUBLICAN PARTY TOTAL | D8: =SUM(E8:O8) -> 10236.76 | E8: =E6 -> 3.62 | F8: =F6 -> 669.83 | G8: =G6 -> 1336.77 | H8: =H6 -> 1203.26 | I8: =I6 -> 1273.19 | J8: =J6 -> 1043.72 | K8: =K6 -> 1250.63 | L8: =L6 -> 1210.05 | ... O8: =O6 -> 225.17
A10: KRISTIN EGAN STATE HOUSE | B10: D | C10: Facebook | D10: =SUM(E10:O10) -> 2966.67 | E10: 0 | F10: 0 | G10: 0 | H10: 0 | I10: 0 | J10: 469.35 | K10: 598.18 | L10: 735.91 | M10: 741.97 | N10: 421.26 | O10: 0
B11: D | C11: KRISTIN EGAN STATE HOUSE Total | D11: =SUM(E11:O11) -> 2966.67 | E11: =SUM(E10:E10) -> 0 | F11: =SUM(F10:F10) -> 0 | G11: =SUM(G10:G10) -> 0 | H11: =SUM(H10:H10) -> 0 | I11: =SUM(I10:I10) -> 0 | J11: =SUM(J10:J10) -> 469.35 | K11: =SUM(K10:K10) -> 598.18 | L11: =SUM(L10:L10) -> 735.91 | ... O11: =SUM(O10:O10) -> 0
A13: BETTER PA | B13: D | C13: CTV | D13: =SUM(E13:O13) -> 288.25 | E13: 0 | F13: 0 | G13: 0 | H13: 0 | I13: 0 | J13: 0 | K13: 0 | L13: 0 | M13: 137.68 | N13: 150.57 | O13: 0
B14: D | C14: BETTER PA Total | D14: =SUM(E14:O14) -> 288.25 | E14: =SUM(E13:E13) -> 0 | F14: =SUM(F13:F13) -> 0 | G14: =SUM(G13:G13) -> 0 | H14: =SUM(H13:H13) -> 0 | I14: =SUM(I13:I13) -> 0 | J14: =SUM(J13:J13) -> 0 | K14: =SUM(K13:K13) -> 0 | L14: =SUM(L13:L13) -> 0 | ... O14: =SUM(O13:O13) -> 0
A16: DEMOCRAT PARTY TOTAL | D16: =SUM(E16:O16) -> 3254.92 | E16: =E11+E14 -> 0 | F16: =F11+F14 -> 0 | G16: =G11+G14 -> 0 | H16: =H11+H14 -> 0 | I16: =I11+I14 -> 0 | J16: =J11+J14 -> 469.35 | K16: =K11+K14 -> 598.18 | L16: =L11+L14 -> 735.91 | ... O16: =O11+O14 -> 0
A18: GRAND TOTAL | D18: =SUM(E18:O18) -> 13491.68 | E18: =E8+E16 -> 3.62 | F18: =F8+F16 -> 669.83 | G18: =G8+G16 -> 1336.77 | H18: =H8+H16 -> 1203.26 | I18: =I8+I16 -> 1273.19 | J18: =J8+J16 -> 1513.07 | K18: =K8+K16 -> 1848.81 | L18: =L8+L16 -> 1945.96 | ... O18: =O8+O16 -> 225.17
A20: Report prepared by GPS Impact | Confidential

Sheet HD-143
A1: HD-143
A3: CANDIDATE / COMMITTEE | B3: PARTY | C3: PLATFORM | D3: TOTAL SPEND | E3: 05/26/2026 | F3: 06/02/2026 | G3: 06/09/2026 | H3: 06/16/2026 | I3: 06/23/2026 | J3: 06/30/2026 | K3: 07/07/2026 | L3: 07/14/2026 | M3: 07/21/2026 | N3: 07/28/2026 | O3: 08/04/2026
A4: RSLC | B4: R | C4: Google | D4: =SUM(E4:O4) -> 8214.72 | E4: 0 | F4: 572.56 | G4: 820.03 | H4: 986.61 | I4: 1048.85 | J4: 825.86 | K4: 1009.37 | L4: 969.49 | M4: 1067.59 | N4: 914.36 | O4: 0
B5: R | C5: Facebook | D5: =SUM(E5:O5) -> 1325.59 | E5: 23.51 | F5: 208.27 | G5: 128.86 | H5: 131.49 | I5: 135.52 | J5: 152.91 | K5: 147.87 | L5: 150.7 | M5: 150.63 | N5: 95.83 | O5: 0
B6: R | C6: RSLC Total | D6: =SUM(E6:O6) -> 9540.31 | E6: =SUM(E4:E5) -> 23.51 | F6: =SUM(F4:F5) -> 780.83 | G6: =SUM(G4:G5) -> 948.89 | H6: =SUM(H4:H5) -> 1118.1 | I6: =SUM(I4:I5) -> 1184.37 | J6: =SUM(J4:J5) -> 978.77 | K6: =SUM(K4:K5) -> 1157.24 | L6: =SUM(L4:L5) -> 1120.19 | ... O6: =SUM(O4:O5) -> 0
A8: REPUBLICAN PARTY TOTAL | D8: =SUM(E8:O8) -> 9540.31 | E8: =E6 -> 23.51 | F8: =F6 -> 780.83 | G8: =G6 -> 948.89 | H8: =H6 -> 1118.1 | I8: =I6 -> 1184.37 | J8: =J6 -> 978.77 | K8: =K6 -> 1157.24 | L8: =L6 -> 1120.19 | ... O8: =O6 -> 0
A10: GRAND TOTAL | D10: =SUM(E10:O10) -> 9540.31 | E10: =E8 -> 23.51 | F10: =F8 -> 780.83 | G10: =G8 -> 948.89 | H10: =H8 -> 1118.1 | I10: =I8 -> 1184.37 | J10: =J8 -> 978.77 | K10: =K8 -> 1157.24 | L10: =L8 -> 1120.19 | ... O10: =O8 -> 0
A12: Report prepared by GPS Impact | Confidential

Sheet HD-144
A1: HD-144
A3: CANDIDATE / COMMITTEE | B3: PARTY | C3: PLATFORM | D3: TOTAL SPEND | E3: 05/26/2026 | F3: 06/02/2026 | G3: 06/09/2026 | H3: 06/16/2026 | I3: 06/23/2026 | J3: 06/30/2026 | K3: 07/07/2026 | L3: 07/14/2026 | M3: 07/21/2026 | N3: 07/28/2026 | O3: 08/04/2026
A4: RSLC | B4: R | C4: Google | D4: =SUM(E4:O4) -> 9464.7 | E4: 0 | F4: 571.26 | G4: 1033.67 | H4: 1327.92 | I4: 1272.83 | J4: 964.51 | K4: 1137.04 | L4: 1082.62 | M4: 1186.55 | N4: 638.11 | O4: 250.19
B5: R | C5: Facebook | D5: =SUM(E5:O5) -> 772.85 | E5: 1.45 | F5: 22.97 | G5: 86.21 | H5: 92.2 | I5: 97.79 | J5: 106.36 | K5: 103.28 | L5: 105.28 | M5: 105.25 | N5: 52.06 | O5: 0
B6: R | C6: RSLC Total | D6: =SUM(E6:O6) -> 10237.55 | E6: =SUM(E4:E5) -> 1.45 | F6: =SUM(F4:F5) -> 594.23 | G6: =SUM(G4:G5) -> 1119.88 | H6: =SUM(H4:H5) -> 1420.12 | I6: =SUM(I4:I5) -> 1370.62 | J6: =SUM(J4:J5) -> 1070.87 | K6: =SUM(K4:K5) -> 1240.32 | L6: =SUM(L4:L5) -> 1187.9 | ... O6: =SUM(O4:O5) -> 250.19
A8: REPUBLICAN PARTY TOTAL | D8: =SUM(E8:O8) -> 10237.55 | E8: =E6 -> 1.45 | F8: =F6 -> 594.23 | G8: =G6 -> 1119.88 | H8: =H6 -> 1420.12 | I8: =I6 -> 1370.62 | J8: =J6 -> 1070.87 | K8: =K6 -> 1240.32 | L8: =L6 -> 1187.9 | ... O8: =O6 -> 250.19
A10: COMMONWEALTH MAJORITY | B10: D | C10: CTV | D10: =SUM(E10:O10) -> 1448.29 | E10: 0 | F10: 26.03 | G10: 127.05 | H10: 142.25 | I10: 182.32 | J10: 180.92 | K10: 238.71 | L10: 203.03 | M10: 204.77 | N10: 143.21 | O10: 0
B11: D | C11: COMMONWEALTH MAJORITY Total | D11: =SUM(E11:O11) -> 1448.29 | E11: =SUM(E10:E10) -> 0 | F11: =SUM(F10:F10) -> 26.03 | G11: =SUM(G10:G10) -> 127.05 | H11: =SUM(H10:H10) -> 142.25 | I11: =SUM(I10:I10) -> 182.32 | J11: =SUM(J10:J10) -> 180.92 | K11: =SUM(K10:K10) -> 238.71 | L11: =SUM(L10:L10) -> 203.03 | ... O11: =SUM(O10:O10) -> 0
A13: BRIAN MUNROE STATE HOUSE | B13: D | C13: Google | D13: =SUM(E13:O13) -> 1300 | E13: 0 | F13: 0 | G13: 0 | H13: 0 | I13: 0 | J13: 0 | K13: 0 | L13: 100 | M13: 600 | N13: 600 | O13: 0
B14: D | C14: BRIAN MUNROE STATE HOUSE Total | D14: =SUM(E14:O14) -> 1300 | E14: =SUM(E13:E13) -> 0 | F14: =SUM(F13:F13) -> 0 | G14: =SUM(G13:G13) -> 0 | H14: =SUM(H13:H13) -> 0 | I14: =SUM(I13:I13) -> 0 | J14: =SUM(J13:J13) -> 0 | K14: =SUM(K13:K13) -> 0 | L14: =SUM(L13:L13) -> 100 | ... O14: =SUM(O13:O13) -> 0
A16: PA HDCC | B16: D | C16: Facebook | D16: =SUM(E16:O16) -> 1190.49 | E16: 0 | F16: 0 | G16: 0 | H16: 0 | I16: 0 | J16: 0 | K16: 199.66 | L16: 349.47 | M16: 349.49 | N16: 291.87 | O16: 0
B17: D | C17: PA HDCC Total | D17: =SUM(E17:O17) -> 1190.49 | E17: =SUM(E16:E16) -> 0 | F17: =SUM(F16:F16) -> 0 | G17: =SUM(G16:G16) -> 0 | H17: =SUM(H16:H16) -> 0 | I17: =SUM(I16:I16) -> 0 | J17: =SUM(J16:J16) -> 0 | K17: =SUM(K16:K16) -> 199.66 | L17: =SUM(L16:L16) -> 349.47 | ... O17: =SUM(O16:O16) -> 0
A19: FAIR DEMOCRACY | B19: D | C19: Facebook | D19: =SUM(E19:O19) -> 56.32 | E19: 19.69 | F19: 36.63 | G19: 0 | H19: 0 | I19: 0 | J19: 0 | K19: 0 | L19: 0 | M19: 0 | N19: 0 | O19: 0
B20: D | C20: FAIR DEMOCRACY Total | D20: =SUM(E20:O20) -> 56.32 | E20: =SUM(E19:E19) -> 19.69 | F20: =SUM(F19:F19) -> 36.63 | G20: =SUM(G19:G19) -> 0 | H20: =SUM(H19:H19) -> 0 | I20: =SUM(I19:I19) -> 0 | J20: =SUM(J19:J19) -> 0 | K20: =SUM(K19:K19) -> 0 | L20: =SUM(L19:L19) -> 0 | ... O20: =SUM(O19:O19) -> 0
A22: DEMOCRAT PARTY TOTAL | D22: =SUM(E22:O22) -> 3995.1 | E22: =E11+E14+E17+E20 -> 19.69 | F22: =F11+F14+F17+F20 -> 62.66 | G22: =G11+G14+G17+G20 -> 127.05 | H22: =H11+H14+H17+H20 -> 142.25 | I22: =I11+I14+I17+I20 -> 182.32 | J22: =J11+J14+J17+J20 -> 180.92 | K22: =K11+K14+K17+K20 -> 438.37 | L22: =L11+L14+L17+L20 -> 652.5 | ... O22: =O11+O14+O17+O20 -> 0
A24: GRAND TOTAL | D24: =SUM(E24:O24) -> 14232.65 | E24: =E8+E22 -> 21.14 | F24: =F8+F22 -> 656.89 | G24: =G8+G22 -> 1246.93 | H24: =H8+H22 -> 1562.37 | I24: =I8+I22 -> 1552.94 | J24: =J8+J22 -> 1251.79 | K24: =K8+K22 -> 1678.69 | L24: =L8+L22 -> 1840.4 | ... O24: =O8+O22 -> 250.19
A26: Report prepared by GPS Impact | Confidential

Sheet HD-147
A1: HD-147
A3: CANDIDATE / COMMITTEE | B3: PARTY | C3: PLATFORM | D3: TOTAL SPEND | E3: 05/26/2026 | F3: 06/02/2026 | G3: 06/09/2026 | H3: 06/16/2026 | I3: 06/23/2026 | J3: 06/30/2026 | K3: 07/07/2026 | L3: 07/14/2026 | M3: 07/21/2026 | N3: 07/28/2026 | O3: 08/04/2026
A4: RSLC | B4: R | C4: Google | D4: =SUM(E4:O4) -> 9688.93 | E4: 0 | F4: 363.12 | G4: 1531.15 | H4: 1254.31 | I4: 1239.15 | J4: 949.19 | K4: 1119.68 | L4: 1074.28 | M4: 1179.84 | N4: 978.21 | O4: 0
B5: R | C5: Facebook | D5: =SUM(E5:O5) -> 1283.57 | E5: 23.09 | F5: 214.44 | G5: 137.55 | H5: 121.65 | I5: 128.52 | J5: 142.32 | K5: 140.13 | L5: 142.83 | M5: 142.81 | N5: 90.23 | O5: 0
B6: R | C6: RSLC Total | D6: =SUM(E6:O6) -> 10972.5 | E6: =SUM(E4:E5) -> 23.09 | F6: =SUM(F4:F5) -> 577.56 | G6: =SUM(G4:G5) -> 1668.7 | H6: =SUM(H4:H5) -> 1375.96 | I6: =SUM(I4:I5) -> 1367.67 | J6: =SUM(J4:J5) -> 1091.51 | K6: =SUM(K4:K5) -> 1259.81 | L6: =SUM(L4:L5) -> 1217.11 | ... O6: =SUM(O4:O5) -> 0
A8: REPUBLICAN PARTY TOTAL | D8: =SUM(E8:O8) -> 10972.5 | E8: =E6 -> 23.09 | F8: =F6 -> 577.56 | G8: =G6 -> 1668.7 | H8: =H6 -> 1375.96 | I8: =I6 -> 1367.67 | J8: =J6 -> 1091.51 | K8: =K6 -> 1259.81 | L8: =L6 -> 1217.11 | ... O8: =O6 -> 0
A10: GRAND TOTAL | D10: =SUM(E10:O10) -> 10972.5 | E10: =E8 -> 23.09 | F10: =F8 -> 577.56 | G10: =G8 -> 1668.7 | H10: =H8 -> 1375.96 | I10: =I8 -> 1367.67 | J10: =J8 -> 1091.51 | K10: =K8 -> 1259.81 | L10: =L8 -> 1217.11 | ... O10: =O8 -> 0
A12: Report prepared by GPS Impact | Confidential

Sheet HD-160
A1: HD-160
A3: CANDIDATE / COMMITTEE | B3: PARTY | C3: PLATFORM | D3: TOTAL SPEND | E3: 05/26/2026 | F3: 06/02/2026 | G3: 06/09/2026 | H3: 06/16/2026 | I3: 06/23/2026 | J3: 06/30/2026 | K3: 07/07/2026 | L3: 07/14/2026 | M3: 07/21/2026 | N3: 07/28/2026 | O3: 08/04/2026
A4: RSLC | B4: R | C4: Google | D4: =SUM(E4:O4) -> 10229.48 | E4: 0 | F4: 712.27 | G4: 1403.77 | H4: 1223.62 | I4: 1281.13 | J4: 996.44 | K4: 1188.78 | L4: 1147.12 | M4: 1260.24 | N4: 1016.11 | O4: 0
B5: R | C5: Facebook | D5: =SUM(E5:O5) -> 1490.8 | E5: 19.03 | F5: 164.22 | G5: 169.71 | H5: 159.84 | I5: 173.9 | J5: 179.27 | K5: 173.45 | L5: 176.77 | M5: 176.69 | N5: 97.92 | O5: 0
B6: R | C6: RSLC Total | D6: =SUM(E6:O6) -> 11720.28 | E6: =SUM(E4:E5) -> 19.03 | F6: =SUM(F4:F5) -> 876.49 | G6: =SUM(G4:G5) -> 1573.48 | H6: =SUM(H4:H5) -> 1383.46 | I6: =SUM(I4:I5) -> 1455.03 | J6: =SUM(J4:J5) -> 1175.71 | K6: =SUM(K4:K5) -> 1362.23 | L6: =SUM(L4:L5) -> 1323.89 | ... O6: =SUM(O4:O5) -> 0
A8: CRAIG WILLIAMS STATE HOUSE | B8: R | C8: Facebook | D8: =SUM(E8:O8) -> 300 | E8: 0 | F8: 0 | G8: 0 | H8: 0 | I8: 0 | J8: 0 | K8: 0 | L8: 0 | M8: 100 | N8: 200 | O8: 0
B9: R | C9: CRAIG WILLIAMS STATE HOUSE Total | D9: =SUM(E9:O9) -> 300 | E9: =SUM(E8:E8) -> 0 | F9: =SUM(F8:F8) -> 0 | G9: =SUM(G8:G8) -> 0 | H9: =SUM(H8:H8) -> 0 | I9: =SUM(I8:I8) -> 0 | J9: =SUM(J8:J8) -> 0 | K9: =SUM(K8:K8) -> 0 | L9: =SUM(L8:L8) -> 0 | ... O9: =SUM(O8:O8) -> 0
A11: REPUBLICAN PARTY TOTAL | D11: =SUM(E11:O11) -> 12020.28 | E11: =E6+E9 -> 19.03 | F11: =F6+F9 -> 876.49 | G11: =G6+G9 -> 1573.48 | H11: =H6+H9 -> 1383.46 | I11: =I6+I9 -> 1455.03 | J11: =J6+J9 -> 1175.71 | K11: =K6+K9 -> 1362.23 | L11: =L6+L9 -> 1323.89 | ... O11: =O6+O9 -> 0
A13: BETTER PA | B13: D | C13: CTV | D13: =SUM(E13:O13) -> 2845.33 | E13: 0 | F13: 3.58 | G13: 22.7 | H13: 32.19 | I13: 62.18 | J13: 41.47 | K13: 48.86 | L13: 38.37 | M13: 1125.63 | N13: 1470.35 | O13: 0
B14: D | C14: Google | D14: =SUM(E14:O14) -> 6988.16 | E14: 0 | F14: 0 | G14: 0 | H14: 0 | I14: 0 | J14: 0 | K14: 0 | L14: 1201.06 | M14: 3206.93 | N14: 2580.17 | O14: 0
B15: D | C15: Facebook | D15: =SUM(E15:O15) -> 2251.55 | E15: 0 | F15: 0 | G15: 0 | H15: 0 | I15: 0 | J15: 0 | K15: 0 | L15: 524.01 | M15: 983.94 | N15: 743.6 | O15: 0
B16: D | C16: BETTER PA Total | D16: =SUM(E16:O16) -> 12085.04 | E16: =SUM(E13:E15) -> 0 | F16: =SUM(F13:F15) -> 3.58 | G16: =SUM(G13:G15) -> 22.7 | H16: =SUM(H13:H15) -> 32.19 | I16: =SUM(I13:I15) -> 62.18 | J16: =SUM(J13:J15) -> 41.47 | K16: =SUM(K13:K15) -> 48.86 | L16: =SUM(L13:L15) -> 1763.44 | ... O16: =SUM(O13:O15) -> 0
A18: PA HDCC | B18: D | C18: Google | D18: =SUM(E18:O18) -> 1016.26 | E18: 0 | F18: 0 | G18: 0 | H18: 0 | I18: 0 | J18: 0 | K18: 100 | L18: 476.89 | M18: 309.33 | N18: 130.04 | O18: 0
B19: D | C19: PA HDCC Total | D19: =SUM(E19:O19) -> 1016.26 | E19: =SUM(E18:E18) -> 0 | F19: =SUM(F18:F18) -> 0 | G19: =SUM(G18:G18) -> 0 | H19: =SUM(H18:H18) -> 0 | I19: =SUM(I18:I18) -> 0 | J19: =SUM(J18:J18) -> 0 | K19: =SUM(K18:K18) -> 100 | L19: =SUM(L18:L18) -> 476.89 | ... O19: =SUM(O18:O18) -> 0
A21: DEMOCRAT PARTY TOTAL | D21: =SUM(E21:O21) -> 13101.3 | E21: =E16+E19 -> 0 | F21: =F16+F19 -> 3.58 | G21: =G16+G19 -> 22.7 | H21: =H16+H19 -> 32.19 | I21: =I16+I19 -> 62.18 | J21: =J16+J19 -> 41.47 | K21: =K16+K19 -> 148.86 | L21: =L16+L19 -> 2240.33 | ... O21: =O16+O19 -> 0
A23: GRAND TOTAL | D23: =SUM(E23:O23) -> 25121.58 | E23: =E11+E21 -> 19.03 | F23: =F11+F21 -> 880.07 | G23: =G11+G21 -> 1596.18 | H23: =H11+H21 -> 1415.65 | I23: =I11+I21 -> 1517.21 | J23: =J11+J21 -> 1217.18 | K23: =K11+K21 -> 1511.09 | L23: =L11+L21 -> 3564.22 | ... O23: =O11+O21 -> 0
A25: Report prepared by GPS Impact | Confidential

Sheet HD-170
A1: HD-170
A3: CANDIDATE / COMMITTEE | B3: PARTY | C3: PLATFORM | D3: TOTAL SPEND | E3: 05/26/2026 | F3: 06/02/2026 | G3: 06/09/2026 | H3: 06/16/2026 | I3: 06/23/2026 | J3: 06/30/2026 | K3: 07/07/2026 | L3: 07/14/2026 | M3: 07/21/2026 | N3: 07/28/2026 | O3: 08/04/2026
A4: RSLC | B4: R | C4: Google | D4: =SUM(E4:O4) -> 9577.31 | E4: 0 | F4: 821.83 | G4: 984.62 | H4: 1160.05 | I4: 1196.07 | J4: 920.29 | K4: 1119.82 | L4: 1070.09 | M4: 1171.94 | N4: 877.69 | O4: 254.91
B5: R | C5: Facebook | D5: =SUM(E5:O5) -> 890.36 | E5: 16.86 | F5: 124.74 | G5: 100.72 | H5: 99.06 | I5: 95.77 | J5: 98.39 | K5: 95.38 | L5: 97.22 | M5: 97.17 | N5: 65.05 | O5: 0
B6: R | C6: RSLC Total | D6: =SUM(E6:O6) -> 10467.67 | E6: =SUM(E4:E5) -> 16.86 | F6: =SUM(F4:F5) -> 946.57 | G6: =SUM(G4:G5) -> 1085.34 | H6: =SUM(H4:H5) -> 1259.11 | I6: =SUM(I4:I5) -> 1291.84 | J6: =SUM(J4:J5) -> 1018.68 | K6: =SUM(K4:K5) -> 1215.2 | L6: =SUM(L4:L5) -> 1167.31 | ... O6: =SUM(O4:O5) -> 254.91
A8: MARTINA WHITE STATE HOUSE | B8: R | C8: Facebook | D8: =SUM(E8:O8) -> 1541.45 | E8: 70.79 | F8: 250 | G8: 350 | H8: 350 | I8: 350 | J8: 170.66 | K8: 0 | L8: 0 | M8: 0 | N8: 0 | O8: 0
B9: R | C9: MARTINA WHITE STATE HOUSE Total | D9: =SUM(E9:O9) -> 1541.45 | E9: =SUM(E8:E8) -> 70.79 | F9: =SUM(F8:F8) -> 250 | G9: =SUM(G8:G8) -> 350 | H9: =SUM(H8:H8) -> 350 | I9: =SUM(I8:I8) -> 350 | J9: =SUM(J8:J8) -> 170.66 | K9: =SUM(K8:K8) -> 0 | L9: =SUM(L8:L8) -> 0 | ... O9: =SUM(O8:O8) -> 0
A11: REPUBLICAN PARTY TOTAL | D11: =SUM(E11:O11) -> 12009.12 | E11: =E6+E9 -> 87.65 | F11: =F6+F9 -> 1196.57 | G11: =G6+G9 -> 1435.34 | H11: =H6+H9 -> 1609.11 | I11: =I6+I9 -> 1641.84 | J11: =J6+J9 -> 1189.34 | K11: =K6+K9 -> 1215.2 | L11: =L6+L9 -> 1167.31 | ... O11: =O6+O9 -> 254.91
A13: GRAND TOTAL | D13: =SUM(E13:O13) -> 12009.12 | E13: =E11 -> 87.65 | F13: =F11 -> 1196.57 | G13: =G11 -> 1435.34 | H13: =H11 -> 1609.11 | I13: =I11 -> 1641.84 | J13: =J11 -> 1189.34 | K13: =K11 -> 1215.2 | L13: =L11 -> 1167.31 | ... O13: =O11 -> 254.91
A15: Report prepared by GPS Impact | Confidential

Sheet HD-187
A1: HD-187
A3: CANDIDATE / COMMITTEE | B3: PARTY | C3: PLATFORM | D3: TOTAL SPEND | E3: 05/26/2026 | F3: 06/02/2026 | G3: 06/09/2026 | H3: 06/16/2026 | I3: 06/23/2026 | J3: 06/30/2026 | K3: 07/07/2026 | L3: 07/14/2026 | M3: 07/21/2026 | N3: 07/28/2026 | O3: 08/04/2026
A4: RSLC | B4: R | C4: Google | D4: =SUM(E4:O4) -> 9832.05 | E4: 0 | F4: 610.17 | G4: 1316.51 | H4: 1180.39 | I4: 1243.66 | J4: 970.53 | K4: 1159.51 | L4: 1118.49 | M4: 1231.59 | N4: 1001.2 | O4: 0
B5: R | C5: Facebook | D5: =SUM(E5:O5) -> 1239.99 | E5: 22.68 | F5: 233.63 | G5: 160.63 | H5: 170.14 | I5: 187.41 | J5: 96.85 | K5: 93.62 | L5: 95.4 | M5: 95.34 | N5: 84.29 | O5: 0
B6: R | C6: RSLC Total | D6: =SUM(E6:O6) -> 11072.04 | E6: =SUM(E4:E5) -> 22.68 | F6: =SUM(F4:F5) -> 843.8 | G6: =SUM(G4:G5) -> 1477.14 | H6: =SUM(H4:H5) -> 1350.53 | I6: =SUM(I4:I5) -> 1431.07 | J6: =SUM(J4:J5) -> 1067.38 | K6: =SUM(K4:K5) -> 1253.13 | L6: =SUM(L4:L5) -> 1213.89 | ... O6: =SUM(O4:O5) -> 0
A8: REPUBLICAN PARTY TOTAL | D8: =SUM(E8:O8) -> 11072.04 | E8: =E6 -> 22.68 | F8: =F6 -> 843.8 | G8: =G6 -> 1477.14 | H8: =H6 -> 1350.53 | I8: =I6 -> 1431.07 | J8: =J6 -> 1067.38 | K8: =K6 -> 1253.13 | L8: =L6 -> 1213.89 | ... O8: =O6 -> 0
A10: GRAND TOTAL | D10: =SUM(E10:O10) -> 11072.04 | E10: =E8 -> 22.68 | F10: =F8 -> 843.8 | G10: =G8 -> 1477.14 | H10: =H8 -> 1350.53 | I10: =I8 -> 1431.07 | J10: =J8 -> 1067.38 | K10: =K8 -> 1253.13 | L10: =L8 -> 1213.89 | ... O10: =O8 -> 0
A12: Report prepared by GPS Impact | Confidential

Sheet SD-6
A1: SD-6
A3: CANDIDATE / COMMITTEE | B3: PARTY | C3: PLATFORM | D3: TOTAL SPEND | E3: 05/26/2026 | F3: 06/02/2026 | G3: 06/09/2026 | H3: 06/16/2026 | I3: 06/23/2026 | J3: 06/30/2026 | K3: 07/07/2026 | L3: 07/14/2026 | M3: 07/21/2026 | N3: 07/28/2026 | O3: 08/04/2026
A4: RSLC | B4: R | C4: Google | D4: =SUM(E4:O4) -> 30812.29 | E4: 0 | F4: 2042.37 | G4: 3508.26 | H4: 3528.11 | I4: 3895.07 | J4: 3104.92 | K4: 3742.16 | L4: 3623.88 | M4: 4017.44 | N4: 3350.08 | O4: 0
B5: R | C5: Facebook | D5: =SUM(E5:O5) -> 4029.48 | E5: 22.38 | F5: 184.28 | G5: 515.65 | H5: 624.59 | I5: 476.13 | J5: 292.79 | K5: 608.24 | L5: 638.64 | M5: 416.23 | N5: 250.55 | O5: 0
B6: R | C6: RSLC Total | D6: =SUM(E6:O6) -> 34841.77 | E6: =SUM(E4:E5) -> 22.38 | F6: =SUM(F4:F5) -> 2226.65 | G6: =SUM(G4:G5) -> 4023.91 | H6: =SUM(H4:H5) -> 4152.7 | I6: =SUM(I4:I5) -> 4371.2 | J6: =SUM(J4:J5) -> 3397.71 | K6: =SUM(K4:K5) -> 4350.4 | L6: =SUM(L4:L5) -> 4262.52 | ... O6: =SUM(O4:O5) -> 0
A8: FRANK FARRY STATE SENATE | B8: R | C8: CTV | D8: =SUM(E8:O8) -> 9.04 | E8: 0 | F8: 0 | G8: 0 | H8: 0 | I8: 0 | J8: 0 | K8: 0 | L8: 0 | M8: 0 | N8: 9.04 | O8: 0
B9: R | C9: Google | D9: =SUM(E9:O9) -> 4765.91 | E9: 0 | F9: 0 | G9: 0 | H9: 0 | I9: 0 | J9: 0 | K9: 0 | L9: 0 | M9: 2747.82 | N9: 1918.09 | O9: 100
B10: R | C10: Facebook | D10: =SUM(E10:O10) -> 29405.76 | E10: 256.99 | F10: 2502.92 | G10: 2375.93 | H10: 2358.88 | I10: 2389.9 | J10: 1886.28 | K10: 4797.62 | L10: 5594.61 | M10: 4842.18 | N10: 2400.45 | O10: 0
B11: R | C11: FRANK FARRY STATE SENATE Total | D11: =SUM(E11:O11) -> 34180.71 | E11: =SUM(E8:E10) -> 256.99 | F11: =SUM(F8:F10) -> 2502.92 | G11: =SUM(G8:G10) -> 2375.93 | H11: =SUM(H8:H10) -> 2358.88 | I11: =SUM(I8:I10) -> 2389.9 | J11: =SUM(J8:J10) -> 1886.28 | K11: =SUM(K8:K10) -> 4797.62 | L11: =SUM(L8:L10) -> 5594.61 | ... O11: =SUM(O8:O10) -> 100
A13: REPUBLICAN PARTY TOTAL | D13: =SUM(E13:O13) -> 69022.48 | E13: =E6+E11 -> 279.37 | F13: =F6+F11 -> 4729.57 | G13: =G6+G11 -> 6399.84 | H13: =H6+H11 -> 6511.58 | I13: =I6+I11 -> 6761.1 | J13: =J6+J11 -> 5283.99 | K13: =K6+K11 -> 9148.02 | L13: =L6+L11 -> 9857.13 | ... O13: =O6+O11 -> 100
A15: BETTER PA | B15: D | C15: Facebook | D15: =SUM(E15:O15) -> 23757.07 | E15: 0 | F15: 0 | G15: 0 | H15: 0 | I15: 5484.89 | J15: 7932.16 | K15: 4784.83 | L15: 5408.65 | M15: 146.54 | N15: 0 | O15: 0
B16: D | C16: BETTER PA Total | D16: =SUM(E16:O16) -> 23757.07 | E16: =SUM(E15:E15) -> 0 | F16: =SUM(F15:F15) -> 0 | G16: =SUM(G15:G15) -> 0 | H16: =SUM(H15:H15) -> 0 | I16: =SUM(I15:I15) -> 5484.89 | J16: =SUM(J15:J15) -> 7932.16 | K16: =SUM(K15:K15) -> 4784.83 | L16: =SUM(L15:L15) -> 5408.65 | ... O16: =SUM(O15:O15) -> 0
A18: DEMOCRAT PARTY TOTAL | D18: =SUM(E18:O18) -> 23757.07 | E18: =E16 -> 0 | F18: =F16 -> 0 | G18: =G16 -> 0 | H18: =H16 -> 0 | I18: =I16 -> 5484.89 | J18: =J16 -> 7932.16 | K18: =K16 -> 4784.83 | L18: =L16 -> 5408.65 | ... O18: =O16 -> 0
A20: GRAND TOTAL | D20: =SUM(E20:O20) -> 92779.55 | E20: =E13+E18 -> 279.37 | F20: =F13+F18 -> 4729.57 | G20: =G13+G18 -> 6399.84 | H20: =H13+H18 -> 6511.58 | I20: =I13+I18 -> 12245.99 | J20: =J13+J18 -> 13216.15 | K20: =K13+K18 -> 13932.85 | L20: =L13+L18 -> 15265.78 | ... O20: =O13+O18 -> 100
A22: Report prepared by GPS Impact | Confidential

Sheet SD-16
A1: SD-16
A3: CANDIDATE / COMMITTEE | B3: PARTY | C3: PLATFORM | D3: TOTAL SPEND | E3: 05/26/2026 | F3: 06/02/2026 | G3: 06/09/2026 | H3: 06/16/2026 | I3: 06/23/2026 | J3: 06/30/2026 | K3: 07/07/2026 | L3: 07/14/2026 | M3: 07/21/2026 | N3: 07/28/2026 | O3: 08/04/2026
A4: RSLC | B4: R | C4: Google | D4: =SUM(E4:O4) -> 30432.13 | E4: 0 | F4: 2021.23 | G4: 2924.44 | H4: 3513.7 | I4: 3851.86 | J4: 3115.17 | K4: 3816.46 | L4: 3711.42 | M4: 4086.93 | N4: 3390.92 | O4: 0
B5: R | C5: Facebook | D5: =SUM(E5:O5) -> 4687.92 | E5: 37.56 | F5: 342.73 | G5: 479.1 | H5: 550.3 | I5: 536.22 | J5: 585.36 | K5: 567.69 | L5: 578.53 | M5: 578.23 | N5: 432.2 | O5: 0
B6: R | C6: RSLC Total | D6: =SUM(E6:O6) -> 35120.05 | E6: =SUM(E4:E5) -> 37.56 | F6: =SUM(F4:F5) -> 2363.96 | G6: =SUM(G4:G5) -> 3403.54 | H6: =SUM(H4:H5) -> 4064 | I6: =SUM(I4:I5) -> 4388.08 | J6: =SUM(J4:J5) -> 3700.53 | K6: =SUM(K4:K5) -> 4384.15 | L6: =SUM(L4:L5) -> 4289.95 | ... O6: =SUM(O4:O5) -> 0
